Workbook

Sheet 사용법
A1: 기록물 실물-보유목록 대조표
A3: 이 파일은 회사 PC에서만 쓰면 됩니다. 자료를 외부로 보낼 필요 없이 엑셀 안에서 자동 대조됩니다.
A5: 1. [설정] 시트 : 보관위치(캐비닛A, 서고 2번 선반 등)와 문서종류를 적어두세요. 실물목록 드롭다운에 나옵니다.
A6: 2. [보유목록] 시트 : 기록물 보유목록 엑셀에서 생산연도·기록물철 제목 등을 복사해 노란 칸에 붙여넣으세요 (최대 3,000행).
A7: - 생산연도: 1900~2099의 4자리. 숫자·텍스트·주변 공백·년 표기를 정리해 대조합니다. 날짜·두 자리·오인식 연도는 입력누락으로 확인하세요.
A8: 3. [실물목록] 시트 : 캐비닛·선반을 돌면서 노란 칸만 채우세요 (최대 1,000행). 파란 칸은 자동 계산됩니다.
A9: - 학교명은 짧게 : '○○초', '○○중'처럼 (보유목록의 '○○초등학교'도 같이 잡힙니다)
A10: - 검색키워드는 띄어쓰기 없는 한 단어 : '환기', '석면', '방수', '냉난방' 등
A11: 4. 대조결과 읽는 법
A12: 있음 : 같은 학교·키워드·연도의 보유 후보가 있음. 문서종류·관리번호·실제 철을 확인한 뒤 처리구분을 정하세요.
A13: 확인필요(연도다름) : 학교·키워드는 맞는데 연도가 다름 → 연도 표기 확인
A14: 확인필요(같은학교·같은연도) : 키워드는 안 맞지만 같은 학교·연도 철이 있음 → 제목 표기가 다를 수 있음
... A24: ※ 회색 줄은 예시입니다. 실제 작성 전에 지워주세요.

Sheet 설정
A1: 보관위치 | C1: 문서종류 | E1: 처리구분 | G1: 노란 칸은 자유롭게 고치거나 추가하세요 (보관위치 30개, 문서종류 20개까지).
A2: 사무실 캐비닛A | C2: 준공도면 | E2: 폐기후보
A3: 사무실 캐비닛B | C3: 설계도면 | E3: 보관
A4: 서고 1번 선반 | C4: 설계보고서 | E4: 등록요청
A5: 서고 2번 선반 | C5: 준공보고서 | E5: 확인필요
C6: 감리보고서
C7: 계약서류
C8: 사진대지
C9: 기타

Sheet 보유목록
A1: 생산연도 | B1: 기록물철 제목 | C1: 보존기간 | D1: 관리번호(철번호) | E1: 비고 | F1: 실물 확인 | G1: 동년 후보 | H1: 대조용 연도 | I1: 대조용 제목
A2: 2019 | B2: 가나초등학교 급식실 환기개선공사 준공도면 | C2: 30년 | D2: 예시-0001 | E2: 예시 (지워주세요) | F2: =IF(B2="","",IF(H2="","확인필요(입력누락)",IF(SUMPRODUCT((실물목록!$P$2:$P$1001<>"")*ISNUMBER(SEARCH(실물목록!$P$2:$P$1001,I2))*(실물목록!$Q$2:$Q$1001<>"")*ISNUMBER(SEARCH(실물목록!$Q$2:$Q$1001,I2))*(실물목록!$R$2:$R$1001="")*(실물목록!$O$2:$O$1001<>"")*(실물목록!$O$2:$O$1001=H2))>0,"실물 있음",IF(SUMPRODUCT((실물목록!$P$2:$P$1001<>"")*ISNUMBER(SEARCH(실물목록!$P$2:$P$1001,I2))*(실물목록!$R$2:$R$1001<>""))>0,"확인필요(입력누락)",IF(SUMPRODUCT((실물목록!$P$2:$P$1001<>"")*ISNUMBER(SEARCH(실물목록!$P$2:$P$1001,I2))*(실물목록!$Q$2:$Q$1001<>"")*ISNUMBER(SEARCH(실물목록!$Q$2:$Q$1001,I2))*(실물목록!$R$2:$R$1001="")*(실물목록!$O$2:$O$1001<>""))>0,"확인필요(연도다름)","실물 없음"))))) | G2: =IF(B2="","",SUMPRODUCT((실물목록!$P$2:$P$1001<>"")*ISNUMBER(SEARCH(실물목록!$P$2:$P$1001,I2))*(실물목록!$Q$2:$Q$1001<>"")*ISNUMBER(SEARCH(실물목록!$Q$2:$Q$1001,I2))*(실물목록!$R$2:$R$1001="")*(실물목록!$O$2:$O$1001<>"")*(실물목록!$O$2:$O$1001=H2))) | H2: =IFERROR(IF(AND(LEN(SUBSTITUTE(SUBSTITUTE(SUBSTITUTE(TRIM(A2&""),CHAR(160),"")," ",""),"년",""))=4,VALUE(SUBSTITUTE(SUBSTITUTE(SUBSTITUTE(TRIM(A2&""),CHAR(160),"")," ",""),"년",""))>=1900,VALUE(SUBSTITUTE(SUBSTITUTE(SUBSTITUTE(TRIM(A2&""),CHAR(160),"")," ",""),"년",""))<=2099,TEXT(VALUE(SUBSTITUTE(SUBSTITUTE(SUBSTITUTE(TRIM(A2&""),CHAR(160),"")," ",""),"년","")),"0000")=SUBSTITUTE(SUBSTITUTE(SUBSTITUTE(TRIM(A2&""),CHAR(160),"")," ",""),"년","")),SUBSTITUTE(SUBSTITUTE(SUBSTITUTE(TRIM(A2&""),CHAR(160),"")," ",""),"년",""),""),"") | I2: =SUBSTITUTE(SUBSTITUTE(SUBSTITUTE(SUBSTITUTE(SUBSTITUTE(TRIM(B2&""),CHAR(160),"")," ",""),"초등학교","초"),"중학교","중"),"고등학교","고")
F3: =IF(B3="","",IF(H3="","확인필요(입력누락)",IF(SUMPRODUCT((실물목록!$P$2:$P$1001<>"")*ISNUMBER(SEARCH(실물목록!$P$2:$P$1001,I3))*(실물목록!$Q$2:$Q$1001<>"")*ISNUMBER(SEARCH(실물목록!$Q$2:$Q$1001,I3))*(실물목록!$R$2:$R$1001="")*(실물목록!$O$2:$O$1001<>"")*(실물목록!$O$2:$O$1001=H3))>0,"실물 있음",IF(SUMPRODUCT((실물목록!$P$2:$P$1001<>"")*ISNUMBER(SEARCH(실물목록!$P$2:$P$1001,I3))*(실물목록!$R$2:$R$1001<>""))>0,"확인필요(입력누락)",IF(SUMPRODUCT((실물목록!$P$2:$P$1001<>"")*ISNUMBER(SEARCH(실물목록!$P$2:$P$1001,I3))*(실물목록!$Q$2:$Q$1001<>"")*ISNUMBER(SEARCH(실물목록!$Q$2:$Q$1001,I3))*(실물목록!$R$2:$R$1001="")*(실물목록!$O$2:$O$1001<>""))>0,"확인필요(연도다름)","실물 없음"))))) | G3: =IF(B3="","",SUMPRODUCT((실물목록!$P$2:$P$1001<>"")*ISNUMBER(SEARCH(실물목록!$P$2:$P$1001,I3))*(실물목록!$Q$2:$Q$1001<>"")*ISNUMBER(SEARCH(실물목록!$Q$2:$Q$1001,I3))*(실물목록!$R$2:$R$1001="")*(실물목록!$O$2:$O$1001<>"")*(실물목록!$O$2:$O$1001=H3))) | H3: =IFERROR(IF(AND(LEN(SUBSTITUTE(SUBSTITUTE(SUBSTITUTE(TRIM(A3&""),CHAR(160),"")," ",""),"년",""))=4,VALUE(SUBSTITUTE(SUBSTITUTE(SUBSTITUTE(TRIM(A3&""),CHAR(160),"")," ",""),"년",""))>=1900,VALUE(SUBSTITUTE(SUBSTITUTE(SUBSTITUTE(TRIM(A3&""),CHAR(160),"")," ",""),"년",""))<=2099,TEXT(VALUE(SUBSTITUTE(SUBSTITUTE(SUBSTITUTE(TRIM(A3&""),CHAR(160),"")," ",""),"년","")),"0000")=SUBSTITUTE(SUBSTITUTE(SUBSTITUTE(TRIM(A3&""),CHAR(160),"")," ",""),"년","")),SUBSTITUTE(SUBSTITUTE(SUBSTITUTE(TRIM(A3&""),CHAR(160),"")," ",""),"년",""),""),"") | I3: =SUBSTITUTE(SUBSTITUTE(SUBSTITUTE(SUBSTITUTE(SUBSTITUTE(TRIM(B3&""),CHAR(160),"")," ",""),"초등학교","초"),"중학교","중"),"고등학교","고")
F4: =IF(B4="","",IF(H4="","확인필요(입력누락)",IF(SUMPRODUCT((실물목록!$P$2:$P$1001<>"")*ISNUMBER(SEARCH(실물목록!$P$2:$P$1001,I4))*(실물목록!$Q$2:$Q$1001<>"")*ISNUMBER(SEARCH(실물목록!$Q$2:$Q$1001,I4))*(실물목록!$R$2:$R$1001="")*(실물목록!$O$2:$O$1001<>"")*(실물목록!$O$2:$O$1001=H4))>0,"실물 있음",IF(SUMPRODUCT((실물목록!$P$2:$P$1001<>"")*ISNUMBER(SEARCH(실물목록!$P$2:$P$1001,I4))*(실물목록!$R$2:$R$1001<>""))>0,"확인필요(입력누락)",IF(SUMPRODUCT((실물목록!$P$2:$P$1001<>"")*ISNUMBER(SEARCH(실물목록!$P$2:$P$1001,I4))*(실물목록!$Q$2:$Q$1001<>"")*ISNUMBER(SEARCH(실물목록!$Q$2:$Q$1001,I4))*(실물목록!$R$2:$R$1001="")*(실물목록!$O$2:$O$1001<>""))>0,"확인필요(연도다름)","실물 없음"))))) | G4: =IF(B4="","",SUMPRODUCT((실물목록!$P$2:$P$1001<>"")*ISNUMBER(SEARCH(실물목록!$P$2:$P$1001,I4))*(실물목록!$Q$2:$Q$1001<>"")*ISNUMBER(SEARCH(실물목록!$Q$2:$Q$1001,I4))*(실물목록!$R$2:$R$1001="")*(실물목록!$O$2:$O$1001<>"")*(실물목록!$O$2:$O$1001=H4))) | H4: =IFERROR(IF(AND(LEN(SUBSTITUTE(SUBSTITUTE(SUBSTITUTE(TRIM(A4&""),CHAR(160),"")," ",""),"년",""))=4,VALUE(SUBSTITUTE(SUBSTITUTE(SUBSTITUTE(TRIM(A4&""),CHAR(160),"")," ",""),"년",""))>=1900,VALUE(SUBSTITUTE(SUBSTITUTE(SUBSTITUTE(TRIM(A4&""),CHAR(160),"")," ",""),"년",""))<=2099,TEXT(VALUE(SUBSTITUTE(SUBSTITUTE(SUBSTITUTE(TRIM(A4&""),CHAR(160),"")," ",""),"년","")),"0000")=SUBSTITUTE(SUBSTITUTE(SUBSTITUTE(TRIM(A4&""),CHAR(160),"")," ",""),"년","")),SUBSTITUTE(SUBSTITUTE(SUBSTITUTE(TRIM(A4&""),CHAR(160),"")," ",""),"년",""),""),"") | I4: =SUBSTITUTE(SUBSTITUTE(SUBSTITUTE(SUBSTITUTE(SUBSTITUTE(TRIM(B4&""),CHAR(160),"")," ",""),"초등학교","초"),"중학교","중"),"고등학교","고")
F5: =IF(B5="","",IF(H5="","확인필요(입력누락)",IF(SUMPRODUCT((실물목록!$P$2:$P$1001<>"")*ISNUMBER(SEARCH(실물목록!$P$2:$P$1001,I5))*(실물목록!$Q$2:$Q$1001<>"")*ISNUMBER(SEARCH(실물목록!$Q$2:$Q$1001,I5))*(실물목록!$R$2:$R$1001="")*(실물목록!$O$2:$O$1001<>"")*(실물목록!$O$2:$O$1001=H5))>0,"실물 있음",IF(SUMPRODUCT((실물목록!$P$2:$P$1001<>"")*ISNUMBER(SEARCH(실물목록!$P$2:$P$1001,I5))*(실물목록!$R$2:$R$1001<>""))>0,"확인필요(입력누락)",IF(SUMPRODUCT((실물목록!$P$2:$P$1001<>"")*ISNUMBER(SEARCH(실물목록!$P$2:$P$1001,I5))*(실물목록!$Q$2:$Q$1001<>"")*ISNUMBER(SEARCH(실물목록!$Q$2:$Q$1001,I5))*(실물목록!$R$2:$R$1001="")*(실물목록!$O$2:$O$1001<>""))>0,"확인필요(연도다름)","실물 없음"))))) | G5: =IF(B5="","",SUMPRODUCT((실물목록!$P$2:$P$1001<>"")*ISNUMBER(SEARCH(실물목록!$P$2:$P$1001,I5))*(실물목록!$Q$2:$Q$1001<>"")*ISNUMBER(SEARCH(실물목록!$Q$2:$Q$1001,I5))*(실물목록!$R$2:$R$1001="")*(실물목록!$O$2:$O$1001<>"")*(실물목록!$O$2:$O$1001=H5))) | H5: =IFERROR(IF(AND(LEN(SUBSTITUTE(SUBSTITUTE(SUBSTITUTE(TRIM(A5&""),CHAR(160),"")," ",""),"년",""))=4,VALUE(SUBSTITUTE(SUBSTITUTE(SUBSTITUTE(TRIM(A5&""),CHAR(160),"")," ",""),"년",""))>=1900,VALUE(SUBSTITUTE(SUBSTITUTE(SUBSTITUTE(TRIM(A5&""),CHAR(160),"")," ",""),"년",""))<=2099,TEXT(VALUE(SUBSTITUTE(SUBSTITUTE(SUBSTITUTE(TRIM(A5&""),CHAR(160),"")," ",""),"년","")),"0000")=SUBSTITUTE(SUBSTITUTE(SUBSTITUTE(TRIM(A5&""),CHAR(160),"")," ",""),"년","")),SUBSTITUTE(SUBSTITUTE(SUBSTITUTE(TRIM(A5&""),CHAR(160),"")," ",""),"년",""),""),"") | I5: =SUBSTITUTE(SUBSTITUTE(SUBSTITUTE(SUBSTITUTE(SUBSTITUTE(TRIM(B5&""),CHAR(160),"")," ",""),"초등학교","초"),"중학교","중"),"고등학교","고")
F6: =IF(B6="","",IF(H6="","확인필요(입력누락)",IF(SUMPRODUCT((실물목록!$P$2:$P$1001<>"")*ISNUMBER(SEARCH(실물목록!$P$2:$P$1001,I6))*(실물목록!$Q$2:$Q$1001<>"")*ISNUMBER(SEARCH(실물목록!$Q$2:$Q$1001,I6))*(실물목록!$R$2:$R$1001="")*(실물목록!$O$2:$O$1001<>"")*(실물목록!$O$2:$O$1001=H6))>0,"실물 있음",IF(SUMPRODUCT((실물목록!$P$2:$P$1001<>"")*ISNUMBER(SEARCH(실물목록!$P$2:$P$1001,I6))*(실물목록!$R$2:$R$1001<>""))>0,"확인필요(입력누락)",IF(SUMPRODUCT((실물목록!$P$2:$P$1001<>"")*ISNUMBER(SEARCH(실물목록!$P$2:$P$1001,I6))*(실물목록!$Q$2:$Q$1001<>"")*ISNUMBER(SEARCH(실물목록!$Q$2:$Q$1001,I6))*(실물목록!$R$2:$R$1001="")*(실물목록!$O$2:$O$1001<>""))>0,"확인필요(연도다름)","실물 없음"))))) | G6: =IF(B6="","",SUMPRODUCT((실물목록!$P$2:$P$1001<>"")*ISNUMBER(SEARCH(실물목록!$P$2:$P$1001,I6))*(실물목록!$Q$2:$Q$1001<>"")*ISNUMBER(SEARCH(실물목록!$Q$2:$Q$1001,I6))*(실물목록!$R$2:$R$1001="")*(실물목록!$O$2:$O$1001<>"")*(실물목록!$O$2:$O$1001=H6))) | H6: =IFERROR(IF(AND(LEN(SUBSTITUTE(SUBSTITUTE(SUBSTITUTE(TRIM(A6&""),CHAR(160),"")," ",""),"년",""))=4,VALUE(SUBSTITUTE(SUBSTITUTE(SUBSTITUTE(TRIM(A6&""),CHAR(160),"")," ",""),"년",""))>=1900,VALUE(SUBSTITUTE(SUBSTITUTE(SUBSTITUTE(TRIM(A6&""),CHAR(160),"")," ",""),"년",""))<=2099,TEXT(VALUE(SUBSTITUTE(SUBSTITUTE(SUBSTITUTE(TRIM(A6&""),CHAR(160),"")," ",""),"년","")),"0000")=SUBSTITUTE(SUBSTITUTE(SUBSTITUTE(TRIM(A6&""),CHAR(160),"")," ",""),"년","")),SUBSTITUTE(SUBSTITUTE(SUBSTITUTE(TRIM(A6&""),CHAR(160),"")," ",""),"년",""),""),"") | I6: =SUBSTITUTE(SUBSTITUTE(SUBSTITUTE(SUBSTITUTE(SUBSTITUTE(TRIM(B6&""),CHAR(160),"")," ",""),"초등학교","초"),"중학교","중"),"고등학교","고")
F7: =IF(B7="","",IF(H7="","확인필요(입력누락)",IF(SUMPRODUCT((실물목록!$P$2:$P$1001<>"")*ISNUMBER(SEARCH(실물목록!$P$2:$P$1001,I7))*(실물목록!$Q$2:$Q$1001<>"")*ISNUMBER(SEARCH(실물목록!$Q$2:$Q$1001,I7))*(실물목록!$R$2:$R$1001="")*(실물목록!$O$2:$O$1001<>"")*(실물목록!$O$2:$O$1001=H7))>0,"실물 있음",IF(SUMPRODUCT((실물목록!$P$2:$P$1001<>"")*ISNUMBER(SEARCH(실물목록!$P$2:$P$1001,I7))*(실물목록!$R$2:$R$1001<>""))>0,"확인필요(입력누락)",IF(SUMPRODUCT((실물목록!$P$2:$P$1001<>"")*ISNUMBER(SEARCH(실물목록!$P$2:$P$1001,I7))*(실물목록!$Q$2:$Q$1001<>"")*ISNUMBER(SEARCH(실물목록!$Q$2:$Q$1001,I7))*(실물목록!$R$2:$R$1001="")*(실물목록!$O$2:$O$1001<>""))>0,"확인필요(연도다름)","실물 없음"))))) | G7: =IF(B7="","",SUMPRODUCT((실물목록!$P$2:$P$1001<>"")*ISNUMBER(SEARCH(실물목록!$P$2:$P$1001,I7))*(실물목록!$Q$2:$Q$1001<>"")*ISNUMBER(SEARCH(실물목록!$Q$2:$Q$1001,I7))*(실물목록!$R$2:$R$1001="")*(실물목록!$O$2:$O$1001<>"")*(실물목록!$O$2:$O$1001=H7))) | H7: =IFERROR(IF(AND(LEN(SUBSTITUTE(SUBSTITUTE(SUBSTITUTE(TRIM(A7&""),CHAR(160),"")," ",""),"년",""))=4,VALUE(SUBSTITUTE(SUBSTITUTE(SUBSTITUTE(TRIM(A7&""),CHAR(160),"")," ",""),"년",""))>=1900,VALUE(SUBSTITUTE(SUBSTITUTE(SUBSTITUTE(TRIM(A7&""),CHAR(160),"")," ",""),"년",""))<=2099,TEXT(VALUE(SUBSTITUTE(SUBSTITUTE(SUBSTITUTE(TRIM(A7&""),CHAR(160),"")," ",""),"년","")),"0000")=SUBSTITUTE(SUBSTITUTE(SUBSTITUTE(TRIM(A7&""),CHAR(160),"")," ",""),"년","")),SUBSTITUTE(SUBSTITUTE(SUBSTITUTE(TRIM(A7&""),CHAR(160),"")," ",""),"년",""),""),"") | I7: =SUBSTITUTE(SUBSTITUTE(SUBSTITUTE(SUBSTITUTE(SUBSTITUTE(TRIM(B7&""),CHAR(160),"")," ",""),"초등학교","초"),"중학교","중"),"고등학교","고")
F8: =IF(B8="","",IF(H8="","확인필요(입력누락)",IF(SUMPRODUCT((실물목록!$P$2:$P$1001<>"")*ISNUMBER(SEARCH(실물목록!$P$2:$P$1001,I8))*(실물목록!$Q$2:$Q$1001<>"")*ISNUMBER(SEARCH(실물목록!$Q$2:$Q$1001,I8))*(실물목록!$R$2:$R$1001="")*(실물목록!$O$2:$O$1001<>"")*(실물목록!$O$2:$O$1001=H8))>0,"실물 있음",IF(SUMPRODUCT((실물목록!$P$2:$P$1001<>"")*ISNUMBER(SEARCH(실물목록!$P$2:$P$1001,I8))*(실물목록!$R$2:$R$1001<>""))>0,"확인필요(입력누락)",IF(SUMPRODUCT((실물목록!$P$2:$P$1001<>"")*ISNUMBER(SEARCH(실물목록!$P$2:$P$1001,I8))*(실물목록!$Q$2:$Q$1001<>"")*ISNUMBER(SEARCH(실물목록!$Q$2:$Q$1001,I8))*(실물목록!$R$2:$R$1001="")*(실물목록!$O$2:$O$1001<>""))>0,"확인필요(연도다름)","실물 없음"))))) | G8: =IF(B8="","",SUMPRODUCT((실물목록!$P$2:$P$1001<>"")*ISNUMBER(SEARCH(실물목록!$P$2:$P$1001,I8))*(실물목록!$Q$2:$Q$1001<>"")*ISNUMBER(SEARCH(실물목록!$Q$2:$Q$1001,I8))*(실물목록!$R$2:$R$1001="")*(실물목록!$O$2:$O$1001<>"")*(실물목록!$O$2:$O$1001=H8))) | H8: =IFERROR(IF(AND(LEN(SUBSTITUTE(SUBSTITUTE(SUBSTITUTE(TRIM(A8&""),CHAR(160),"")," ",""),"년",""))=4,VALUE(SUBSTITUTE(SUBSTITUTE(SUBSTITUTE(TRIM(A8&""),CHAR(160),"")," ",""),"년",""))>=1900,VALUE(SUBSTITUTE(SUBSTITUTE(SUBSTITUTE(TRIM(A8&""),CHAR(160),"")," ",""),"년",""))<=2099,TEXT(VALUE(SUBSTITUTE(SUBSTITUTE(SUBSTITUTE(TRIM(A8&""),CHAR(160),"")," ",""),"년","")),"0000")=SUBSTITUTE(SUBSTITUTE(SUBSTITUTE(TRIM(A8&""),CHAR(160),"")," ",""),"년","")),SUBSTITUTE(SUBSTITUTE(SUBSTITUTE(TRIM(A8&""),CHAR(160),"")," ",""),"년",""),""),"") | I8: =SUBSTITUTE(SUBSTITUTE(SUBSTITUTE(SUBSTITUTE(SUBSTITUTE(TRIM(B8&""),CHAR(160),"")," ",""),"초등학교","초"),"중학교","중"),"고등학교","고")
F9: =IF(B9="","",IF(H9="","확인필요(입력누락)",IF(SUMPRODUCT((실물목록!$P$2:$P$1001<>"")*ISNUMBER(SEARCH(실물목록!$P$2:$P$1001,I9))*(실물목록!$Q$2:$Q$1001<>"")*ISNUMBER(SEARCH(실물목록!$Q$2:$Q$1001,I9))*(실물목록!$R$2:$R$1001="")*(실물목록!$O$2:$O$1001<>"")*(실물목록!$O$2:$O$1001=H9))>0,"실물 있음",IF(SUMPRODUCT((실물목록!$P$2:$P$1001<>"")*ISNUMBER(SEARCH(실물목록!$P$2:$P$1001,I9))*(실물목록!$R$2:$R$1001<>""))>0,"확인필요(입력누락)",IF(SUMPRODUCT((실물목록!$P$2:$P$1001<>"")*ISNUMBER(SEARCH(실물목록!$P$2:$P$1001,I9))*(실물목록!$Q$2:$Q$1001<>"")*ISNUMBER(SEARCH(실물목록!$Q$2:$Q$1001,I9))*(실물목록!$R$2:$R$1001="")*(실물목록!$O$2:$O$1001<>""))>0,"확인필요(연도다름)","실물 없음"))))) | G9: =IF(B9="","",SUMPRODUCT((실물목록!$P$2:$P$1001<>"")*ISNUMBER(SEARCH(실물목록!$P$2:$P$1001,I9))*(실물목록!$Q$2:$Q$1001<>"")*ISNUMBER(SEARCH(실물목록!$Q$2:$Q$1001,I9))*(실물목록!$R$2:$R$1001="")*(실물목록!$O$2:$O$1001<>"")*(실물목록!$O$2:$O$1001=H9))) | H9: =IFERROR(IF(AND(LEN(SUBSTITUTE(SUBSTITUTE(SUBSTITUTE(TRIM(A9&""),CHAR(160),"")," ",""),"년",""))=4,VALUE(SUBSTITUTE(SUBSTITUTE(SUBSTITUTE(TRIM(A9&""),CHAR(160),"")," ",""),"년",""))>=1900,VALUE(SUBSTITUTE(SUBSTITUTE(SUBSTITUTE(TRIM(A9&""),CHAR(160),"")," ",""),"년",""))<=2099,TEXT(VALUE(SUBSTITUTE(SUBSTITUTE(SUBSTITUTE(TRIM(A9&""),CHAR(160),"")," ",""),"년","")),"0000")=SUBSTITUTE(SUBSTITUTE(SUBSTITUTE(TRIM(A9&""),CHAR(160),"")," ",""),"년","")),SUBSTITUTE(SUBSTITUTE(SUBSTITUTE(TRIM(A9&""),CHAR(160),"")," ",""),"년",""),""),"") | I9: =SUBSTITUTE(SUBSTITUTE(SUBSTITUTE(SUBSTITUTE(SUBSTITUTE(TRIM(B9&""),CHAR(160),"")," ",""),"초등학교","초"),"중학교","중"),"고등학교","고")
F10: =IF(B10="","",IF(H10="","확인필요(입력누락)",IF(SUMPRODUCT((실물목록!$P$2:$P$1001<>"")*ISNUMBER(SEARCH(실물목록!$P$2:$P$1001,I10))*(실물목록!$Q$2:$Q$1001<>"")*ISNUMBER(SEARCH(실물목록!$Q$2:$Q$1001,I10))*(실물목록!$R$2:$R$1001="")*(실물목록!$O$2:$O$1001<>"")*(실물목록!$O$2:$O$1001=H10))>0,"실물 있음",IF(SUMPRODUCT((실물목록!$P$2:$P$1001<>"")*ISNUMBER(SEARCH(실물목록!$P$2:$P$1001,I10))*(실물목록!$R$2:$R$1001<>""))>0,"확인필요(입력누락)",IF(SUMPRODUCT((실물목록!$P$2:$P$1001<>"")*ISNUMBER(SEARCH(실물목록!$P$2:$P$1001,I10))*(실물목록!$Q$2:$Q$1001<>"")*ISNUMBER(SEARCH(실물목록!$Q$2:$Q$1001,I10))*(실물목록!$R$2:$R$1001="")*(실물목록!$O$2:$O$1001<>""))>0,"확인필요(연도다름)","실물 없음"))))) | G10: =IF(B10="","",SUMPRODUCT((실물목록!$P$2:$P$1001<>"")*ISNUMBER(SEARCH(실물목록!$P$2:$P$1001,I10))*(실물목록!$Q$2:$Q$1001<>"")*ISNUMBER(SEARCH(실물목록!$Q$2:$Q$1001,I10))*(실물목록!$R$2:$R$1001="")*(실물목록!$O$2:$O$1001<>"")*(실물목록!$O$2:$O$1001=H10))) | H10: =IFERROR(IF(AND(LEN(SUBSTITUTE(SUBSTITUTE(SUBSTITUTE(TRIM(A10&""),CHAR(160),"")," ",""),"년",""))=4,VALUE(SUBSTITUTE(SUBSTITUTE(SUBSTITUTE(TRIM(A10&""),CHAR(160),"")," ",""),"년",""))>=1900,VALUE(SUBSTITUTE(SUBSTITUTE(SUBSTITUTE(TRIM(A10&""),CHAR(160),"")," ",""),"년",""))<=2099,TEXT(VALUE(SUBSTITUTE(SUBSTITUTE(SUBSTITUTE(TRIM(A10&""),CHAR(160),"")," ",""),"년","")),"0000")=SUBSTITUTE(SUBSTITUTE(SUBSTITUTE(TRIM(A10&""),CHAR(160),"")," ",""),"년","")),SUBSTITUTE(SUBSTITUTE(SUBSTITUTE(TRIM(A10&""),CHAR(160),"")," ",""),"년",""),""),"") | I10: =SUBSTITUTE(SUBSTITUTE(SUBSTITUTE(SUBSTITUTE(SUBSTITUTE(TRIM(B10&""),CHAR(160),"")," ",""),"초등학교","초"),"중학교","중"),"고등학교","고")
F11: =IF(B11="","",IF(H11="","확인필요(입력누락)",IF(SUMPRODUCT((실물목록!$P$2:$P$1001<>"")*ISNUMBER(SEARCH(실물목록!$P$2:$P$1001,I11))*(실물목록!$Q$2:$Q$1001<>"")*ISNUMBER(SEARCH(실물목록!$Q$2:$Q$1001,I11))*(실물목록!$R$2:$R$1001="")*(실물목록!$O$2:$O$1001<>"")*(실물목록!$O$2:$O$1001=H11))>0,"실물 있음",IF(SUMPRODUCT((실물목록!$P$2:$P$1001<>"")*ISNUMBER(SEARCH(실물목록!$P$2:$P$1001,I11))*(실물목록!$R$2:$R$1001<>""))>0,"확인필요(입력누락)",IF(SUMPRODUCT((실물목록!$P$2:$P$1001<>"")*ISNUMBER(SEARCH(실물목록!$P$2:$P$1001,I11))*(실물목록!$Q$2:$Q$1001<>"")*ISNUMBER(SEARCH(실물목록!$Q$2:$Q$1001,I11))*(실물목록!$R$2:$R$1001="")*(실물목록!$O$2:$O$1001<>""))>0,"확인필요(연도다름)","실물 없음"))))) | G11: =IF(B11="","",SUMPRODUCT((실물목록!$P$2:$P$1001<>"")*ISNUMBER(SEARCH(실물목록!$P$2:$P$1001,I11))*(실물목록!$Q$2:$Q$1001<>"")*ISNUMBER(SEARCH(실물목록!$Q$2:$Q$1001,I11))*(실물목록!$R$2:$R$1001="")*(실물목록!$O$2:$O$1001<>"")*(실물목록!$O$2:$O$1001=H11))) | H11: =IFERROR(IF(AND(LEN(SUBSTITUTE(SUBSTITUTE(SUBSTITUTE(TRIM(A11&""),CHAR(160),"")," ",""),"년",""))=4,VALUE(SUBSTITUTE(SUBSTITUTE(SUBSTITUTE(TRIM(A11&""),CHAR(160),"")," ",""),"년",""))>=1900,VALUE(SUBSTITUTE(SUBSTITUTE(SUBSTITUTE(TRIM(A11&""),CHAR(160),"")," ",""),"년",""))<=2099,TEXT(VALUE(SUBSTITUTE(SUBSTITUTE(SUBSTITUTE(TRIM(A11&""),CHAR(160),"")," ",""),"년","")),"0000")=SUBSTITUTE(SUBSTITUTE(SUBSTITUTE(TRIM(A11&""),CHAR(160),"")," ",""),"년","")),SUBSTITUTE(SUBSTITUTE(SUBSTITUTE(TRIM(A11&""),CHAR(160),"")," ",""),"년",""),""),"") | I11: =SUBSTITUTE(SUBSTITUTE(SUBSTITUTE(SUBSTITUTE(SUBSTITUTE(TRIM(B11&""),CHAR(160),"")," ",""),"초등학교","초"),"중학교","중"),"고등학교","고")
F12: =IF(B12="","",IF(H12="","확인필요(입력누락)",IF(SUMPRODUCT((실물목록!$P$2:$P$1001<>"")*ISNUMBER(SEARCH(실물목록!$P$2:$P$1001,I12))*(실물목록!$Q$2:$Q$1001<>"")*ISNUMBER(SEARCH(실물목록!$Q$2:$Q$1001,I12))*(실물목록!$R$2:$R$1001="")*(실물목록!$O$2:$O$1001<>"")*(실물목록!$O$2:$O$1001=H12))>0,"실물 있음",IF(SUMPRODUCT((실물목록!$P$2:$P$1001<>"")*ISNUMBER(SEARCH(실물목록!$P$2:$P$1001,I12))*(실물목록!$R$2:$R$1001<>""))>0,"확인필요(입력누락)",IF(SUMPRODUCT((실물목록!$P$2:$P$1001<>"")*ISNUMBER(SEARCH(실물목록!$P$2:$P$1001,I12))*(실물목록!$Q$2:$Q$1001<>"")*ISNUMBER(SEARCH(실물목록!$Q$2:$Q$1001,I12))*(실물목록!$R$2:$R$1001="")*(실물목록!$O$2:$O$1001<>""))>0,"확인필요(연도다름)","실물 없음"))))) | G12: =IF(B12="","",SUMPRODUCT((실물목록!$P$2:$P$1001<>"")*ISNUMBER(SEARCH(실물목록!$P$2:$P$1001,I12))*(실물목록!$Q$2:$Q$1001<>"")*ISNUMBER(SEARCH(실물목록!$Q$2:$Q$1001,I12))*(실물목록!$R$2:$R$1001="")*(실물목록!$O$2:$O$1001<>"")*(실물목록!$O$2:$O$1001=H12))) | H12: =IFERROR(IF(AND(LEN(SUBSTITUTE(SUBSTITUTE(SUBSTITUTE(TRIM(A12&""),CHAR(160),"")," ",""),"년",""))=4,VALUE(SUBSTITUTE(SUBSTITUTE(SUBSTITUTE(TRIM(A12&""),CHAR(160),"")," ",""),"년",""))>=1900,VALUE(SUBSTITUTE(SUBSTITUTE(SUBSTITUTE(TRIM(A12&""),CHAR(160),"")," ",""),"년",""))<=2099,TEXT(VALUE(SUBSTITUTE(SUBSTITUTE(SUBSTITUTE(TRIM(A12&""),CHAR(160),"")," ",""),"년","")),"0000")=SUBSTITUTE(SUBSTITUTE(SUBSTITUTE(TRIM(A12&""),CHAR(160),"")," ",""),"년","")),SUBSTITUTE(SUBSTITUTE(SUBSTITUTE(TRIM(A12&""),CHAR(160),"")," ",""),"년",""),""),"") | I12: =SUBSTITUTE(SUBSTITUTE(SUBSTITUTE(SUBSTITUTE(SUBSTITUTE(TRIM(B12&""),CHAR(160),"")," ",""),"초등학교","초"),"중학교","중"),"고등학교","고")
F13: =IF(B13="","",IF(H13="","확인필요(입력누락)",IF(SUMPRODUCT((실물목록!$P$2:$P$1001<>"")*ISNUMBER(SEARCH(실물목록!$P$2:$P$1001,I13))*(실물목록!$Q$2:$Q$1001<>"")*ISNUMBER(SEARCH(실물목록!$Q$2:$Q$1001,I13))*(실물목록!$R$2:$R$1001="")*(실물목록!$O$2:$O$1001<>"")*(실물목록!$O$2:$O$1001=H13))>0,"실물 있음",IF(SUMPRODUCT((실물목록!$P$2:$P$1001<>"")*ISNUMBER(SEARCH(실물목록!$P$2:$P$1001,I13))*(실물목록!$R$2:$R$1001<>""))>0,"확인필요(입력누락)",IF(SUMPRODUCT((실물목록!$P$2:$P$1001<>"")*ISNUMBER(SEARCH(실물목록!$P$2:$P$1001,I13))*(실물목록!$Q$2:$Q$1001<>"")*ISNUMBER(SEARCH(실물목록!$Q$2:$Q$1001,I13))*(실물목록!$R$2:$R$1001="")*(실물목록!$O$2:$O$1001<>""))>0,"확인필요(연도다름)","실물 없음"))))) | G13: =IF(B13="","",SUMPRODUCT((실물목록!$P$2:$P$1001<>"")*ISNUMBER(SEARCH(실물목록!$P$2:$P$1001,I13))*(실물목록!$Q$2:$Q$1001<>"")*ISNUMBER(SEARCH(실물목록!$Q$2:$Q$1001,I13))*(실물목록!$R$2:$R$1001="")*(실물목록!$O$2:$O$1001<>"")*(실물목록!$O$2:$O$1001=H13))) | H13: =IFERROR(IF(AND(LEN(SUBSTITUTE(SUBSTITUTE(SUBSTITUTE(TRIM(A13&""),CHAR(160),"")," ",""),"년",""))=4,VALUE(SUBSTITUTE(SUBSTITUTE(SUBSTITUTE(TRIM(A13&""),CHAR(160),"")," ",""),"년",""))>=1900,VALUE(SUBSTITUTE(SUBSTITUTE(SUBSTITUTE(TRIM(A13&""),CHAR(160),"")," ",""),"년",""))<=2099,TEXT(VALUE(SUBSTITUTE(SUBSTITUTE(SUBSTITUTE(TRIM(A13&""),CHAR(160),"")," ",""),"년","")),"0000")=SUBSTITUTE(SUBSTITUTE(SUBSTITUTE(TRIM(A13&""),CHAR(160),"")," ",""),"년","")),SUBSTITUTE(SUBSTITUTE(SUBSTITUTE(TRIM(A13&""),CHAR(160),"")," ",""),"년",""),""),"") | I13: =SUBSTITUTE(SUBSTITUTE(SUBSTITUTE(SUBSTITUTE(SUBSTITUTE(TRIM(B13&""),CHAR(160),"")," ",""),"초등학교","초"),"중학교","중"),"고등학교","고")
F14: =IF(B14="","",IF(H14="","확인필요(입력누락)",IF(SUMPRODUCT((실물목록!$P$2:$P$1001<>"")*ISNUMBER(SEARCH(실물목록!$P$2:$P$1001,I14))*(실물목록!$Q$2:$Q$1001<>"")*ISNUMBER(SEARCH(실물목록!$Q$2:$Q$1001,I14))*(실물목록!$R$2:$R$1001="")*(실물목록!$O$2:$O$1001<>"")*(실물목록!$O$2:$O$1001=H14))>0,"실물 있음",IF(SUMPRODUCT((실물목록!$P$2:$P$1001<>"")*ISNUMBER(SEARCH(실물목록!$P$2:$P$1001,I14))*(실물목록!$R$2:$R$1001<>""))>0,"확인필요(입력누락)",IF(SUMPRODUCT((실물목록!$P$2:$P$1001<>"")*ISNUMBER(SEARCH(실물목록!$P$2:$P$1001,I14))*(실물목록!$Q$2:$Q$1001<>"")*ISNUMBER(SEARCH(실물목록!$Q$2:$Q$1001,I14))*(실물목록!$R$2:$R$1001="")*(실물목록!$O$2:$O$1001<>""))>0,"확인필요(연도다름)","실물 없음"))))) | G14: =IF(B14="","",SUMPRODUCT((실물목록!$P$2:$P$1001<>"")*ISNUMBER(SEARCH(실물목록!$P$2:$P$1001,I14))*(실물목록!$Q$2:$Q$1001<>"")*ISNUMBER(SEARCH(실물목록!$Q$2:$Q$1001,I14))*(실물목록!$R$2:$R$1001="")*(실물목록!$O$2:$O$1001<>"")*(실물목록!$O$2:$O$1001=H14))) | H14: =IFERROR(IF(AND(LEN(SUBSTITUTE(SUBSTITUTE(SUBSTITUTE(TRIM(A14&""),CHAR(160),"")," ",""),"년",""))=4,VALUE(SUBSTITUTE(SUBSTITUTE(SUBSTITUTE(TRIM(A14&""),CHAR(160),"")," ",""),"년",""))>=1900,VALUE(SUBSTITUTE(SUBSTITUTE(SUBSTITUTE(TRIM(A14&""),CHAR(160),"")," ",""),"년",""))<=2099,TEXT(VALUE(SUBSTITUTE(SUBSTITUTE(SUBSTITUTE(TRIM(A14&""),CHAR(160),"")," ",""),"년","")),"0000")=SUBSTITUTE(SUBSTITUTE(SUBSTITUTE(TRIM(A14&""),CHAR(160),"")," ",""),"년","")),SUBSTITUTE(SUBSTITUTE(SUBSTITUTE(TRIM(A14&""),CHAR(160),"")," ",""),"년",""),""),"") | I14: =SUBSTITUTE(SUBSTITUTE(SUBSTITUTE(SUBSTITUTE(SUBSTITUTE(TRIM(B14&""),CHAR(160),"")," ",""),"초등학교","초"),"중학교","중"),"고등학교","고")
... F3001: =IF(B3001="","",IF(H3001="","확인필요(입력누락)",IF(SUMPRODUCT((실물목록!$P$2:$P$1001<>"")*ISNUMBER(SEARCH(실물목록!$P$2:$P$1001,I3001))*(실물목록!$Q$2:$Q$1001<>"")*ISNUMBER(SEARCH(실물목록!$Q$2:$Q$1001,I3001))*(실물목록!$R$2:$R$1001="")*(실물목록!$O$2:$O$1001<>"")*(실물목록!$O$2:$O$1001=H3001))>0,"실물 있음",IF(SUMPRODUCT((실물목록!$P$2:$P$1001<>"")*ISNUMBER(SEARCH(실물목록!$P$2:$P$1001,I3001))*(실물목록!$R$2:$R$1001<>""))>0,"확인필요(입력누락)",IF(SUMPRODUCT((실물목록!$P$2:$P$1001<>"")*ISNUMBER(SEARCH(실물목록!$P$2:$P$1001,I3001))*(실물목록!$Q$2:$Q$1001<>"")*ISNUMBER(SEARCH(실물목록!$Q$2:$Q$1001,I3001))*(실물목록!$R$2:$R$1001="")*(실물목록!$O$2:$O$1001<>""))>0,"확인필요(연도다름)","실물 없음"))))) | G3001: =IF(B3001="","",SUMPRODUCT((실물목록!$P$2:$P$1001<>"")*ISNUMBER(SEARCH(실물목록!$P$2:$P$1001,I3001))*(실물목록!$Q$2:$Q$1001<>"")*ISNUMBER(SEARCH(실물목록!$Q$2:$Q$1001,I3001))*(실물목록!$R$2:$R$1001="")*(실물목록!$O$2:$O$1001<>"")*(실물목록!$O$2:$O$1001=H3001))) | H3001: =IFERROR(IF(AND(LEN(SUBSTITUTE(SUBSTITUTE(SUBSTITUTE(TRIM(A3001&""),CHAR(160),"")," ",""),"년",""))=4,VALUE(SUBSTITUTE(SUBSTITUTE(SUBSTITUTE(TRIM(A3001&""),CHAR(160),"")," ",""),"년",""))>=1900,VALUE(SUBSTITUTE(SUBSTITUTE(SUBSTITUTE(TRIM(A3001&""),CHAR(160),"")," ",""),"년",""))<=2099,TEXT(VALUE(SUBSTITUTE(SUBSTITUTE(SUBSTITUTE(TRIM(A3001&""),CHAR(160),"")," ",""),"년","")),"0000")=SUBSTITUTE(SUBSTITUTE(SUBSTITUTE(TRIM(A3001&""),CHAR(160),"")," ",""),"년","")),SUBSTITUTE(SUBSTITUTE(SUBSTITUTE(TRIM(A3001&""),CHAR(160),"")," ",""),"년",""),""),"") | I3001: =SUBSTITUTE(SUBSTITUTE(SUBSTITUTE(SUBSTITUTE(SUBSTITUTE(TRIM(B3001&""),CHAR(160),"")," ",""),"초등학교","초"),"중학교","중"),"고등학교","고")

Sheet 실물목록
A1: 번호 | B1: 보관위치 | C1: 생산연도 | D1: 학교명 | E1: 검색키워드 | F1: 실물 제목(바인더 표기 그대로) | G1: 문서종류 | H1: 권수 | I1: 원본/사본 | J1: 메모 | K1: 대조결과 | L1: 일치 건수 | M1: 보유목록 후보 제목 | N1: 처리구분 | O1: 대조용 연도 | P1: 대조용 학교 | Q1: 대조용 키워드 | R1: 입력 확인
A2: =IF(COUNTA(B2:J2)=0,"",ROW()-1) | B2: 사무실 캐비닛A | C2: 2019 | D2: 가나초 | E2: 환기 | F2: 가나초 급식실 환기개선 준공도면 | G2: 준공도면 | H2: 1 | I2: 사본 | J2: 예시 (지워주세요) | K2: =IF(COUNTA(B2:J2)=0,"",IF(R2<>"","확인필요(입력누락)",IF(COUNTIFS(보유목록!$I$2:$I$3001,"*"&P2&"*",보유목록!$I$2:$I$3001,"*"&Q2&"*",보유목록!$H$2:$H$3001,O2)>0,"있음",IF(COUNTIFS(보유목록!$I$2:$I$3001,"*"&P2&"*",보유목록!$I$2:$I$3001,"*"&Q2&"*")>0,"확인필요(연도다름)",IF(COUNTIFS(보유목록!$I$2:$I$3001,"*"&P2&"*",보유목록!$H$2:$H$3001,O2)>0,"확인필요(같은학교·같은연도)","없음"))))) | L2: =IF(OR(COUNTA(B2:J2)=0,R2<>""),"",COUNTIFS(보유목록!$I$2:$I$3001,"*"&P2&"*",보유목록!$I$2:$I$3001,"*"&Q2&"*")) | M2: =IF(OR(COUNTA(B2:J2)=0,R2<>""),"",IFERROR(LOOKUP(2,1/(ISNUMBER(SEARCH(P2,보유목록!$I$2:$I$3001))*ISNUMBER(SEARCH(Q2,보유목록!$I$2:$I$3001))*(보유목록!$H$2:$H$3001=O2)),보유목록!$B$2:$B$3001),IFERROR(LOOKUP(2,1/(ISNUMBER(SEARCH(P2,보유목록!$I$2:$I$3001))*ISNUMBER(SEARCH(Q2,보유목록!$I$2:$I$3001))),보유목록!$B$2:$B$3001),""))) | N2: 폐기후보 | O2: =IFERROR(IF(AND(LEN(SUBSTITUTE(SUBSTITUTE(SUBSTITUTE(TRIM(C2&""),CHAR(160),"")," ",""),"년",""))=4,VALUE(SUBSTITUTE(SUBSTITUTE(SUBSTITUTE(TRIM(C2&""),CHAR(160),"")," ",""),"년",""))>=1900,VALUE(SUBSTITUTE(SUBSTITUTE(SUBSTITUTE(TRIM(C2&""),CHAR(160),"")," ",""),"년",""))<=2099,TEXT(VALUE(SUBSTITUTE(SUBSTITUTE(SUBSTITUTE(TRIM(C2&""),CHAR(160),"")," ",""),"년","")),"0000")=SUBSTITUTE(SUBSTITUTE(SUBSTITUTE(TRIM(C2&""),CHAR(160),"")," ",""),"년","")),SUBSTITUTE(SUBSTITUTE(SUBSTITUTE(TRIM(C2&""),CHAR(160),"")," ",""),"년",""),""),"") | P2: =SUBSTITUTE(SUBSTITUTE(SUBSTITUTE(SUBSTITUTE(SUBSTITUTE(SUBSTITUTE(SUBSTITUTE(SUBSTITUTE(TRIM(D2&""),CHAR(160),"")," ",""),"초등학교","초"),"중학교","중"),"고등학교","고"),"~","~~"),"*","~*"),"?","~?") | Q2: =SUBSTITUTE(SUBSTITUTE(SUBSTITUTE(SUBSTITUTE(SUBSTITUTE(SUBSTITUTE(SUBSTITUTE(SUBSTITUTE(TRIM(E2&""),CHAR(160),"")," ",""),"초등학교","초"),"중학교","중"),"고등학교","고"),"~","~~"),"*","~*"),"?","~?") | R2: =IF(COUNTA(B2:J2)=0,"",IF(AND(O2<>"",P2<>"",Q2<>""),"","입력누락"))
A3: =IF(COUNTA(B3:J3)=0,"",ROW()-1) | K3: =IF(COUNTA(B3:J3)=0,"",IF(R3<>"","확인필요(입력누락)",IF(COUNTIFS(보유목록!$I$2:$I$3001,"*"&P3&"*",보유목록!$I$2:$I$3001,"*"&Q3&"*",보유목록!$H$2:$H$3001,O3)>0,"있음",IF(COUNTIFS(보유목록!$I$2:$I$3001,"*"&P3&"*",보유목록!$I$2:$I$3001,"*"&Q3&"*")>0,"확인필요(연도다름)",IF(COUNTIFS(보유목록!$I$2:$I$3001,"*"&P3&"*",보유목록!$H$2:$H$3001,O3)>0,"확인필요(같은학교·같은연도)","없음"))))) | L3: =IF(OR(COUNTA(B3:J3)=0,R3<>""),"",COUNTIFS(보유목록!$I$2:$I$3001,"*"&P3&"*",보유목록!$I$2:$I$3001,"*"&Q3&"*")) | M3: =IF(OR(COUNTA(B3:J3)=0,R3<>""),"",IFERROR(LOOKUP(2,1/(ISNUMBER(SEARCH(P3,보유목록!$I$2:$I$3001))*ISNUMBER(SEARCH(Q3,보유목록!$I$2:$I$3001))*(보유목록!$H$2:$H$3001=O3)),보유목록!$B$2:$B$3001),IFERROR(LOOKUP(2,1/(ISNUMBER(SEARCH(P3,보유목록!$I$2:$I$3001))*ISNUMBER(SEARCH(Q3,보유목록!$I$2:$I$3001))),보유목록!$B$2:$B$3001),""))) | O3: =IFERROR(IF(AND(LEN(SUBSTITUTE(SUBSTITUTE(SUBSTITUTE(TRIM(C3&""),CHAR(160),"")," ",""),"년",""))=4,VALUE(SUBSTITUTE(SUBSTITUTE(SUBSTITUTE(TRIM(C3&""),CHAR(160),"")," ",""),"년",""))>=1900,VALUE(SUBSTITUTE(SUBSTITUTE(SUBSTITUTE(TRIM(C3&""),CHAR(160),"")," ",""),"년",""))<=2099,TEXT(VALUE(SUBSTITUTE(SUBSTITUTE(SUBSTITUTE(TRIM(C3&""),CHAR(160),"")," ",""),"년","")),"0000")=SUBSTITUTE(SUBSTITUTE(SUBSTITUTE(TRIM(C3&""),CHAR(160),"")," ",""),"년","")),SUBSTITUTE(SUBSTITUTE(SUBSTITUTE(TRIM(C3&""),CHAR(160),"")," ",""),"년",""),""),"") | P3: =SUBSTITUTE(SUBSTITUTE(SUBSTITUTE(SUBSTITUTE(SUBSTITUTE(SUBSTITUTE(SUBSTITUTE(SUBSTITUTE(TRIM(D3&""),CHAR(160),"")," ",""),"초등학교","초"),"중학교","중"),"고등학교","고"),"~","~~"),"*","~*"),"?","~?") | Q3: =SUBSTITUTE(SUBSTITUTE(SUBSTITUTE(SUBSTITUTE(SUBSTITUTE(SUBSTITUTE(SUBSTITUTE(SUBSTITUTE(TRIM(E3&""),CHAR(160),"")," ",""),"초등학교","초"),"중학교","중"),"고등학교","고"),"~","~~"),"*","~*"),"?","~?") | R3: =IF(COUNTA(B3:J3)=0,"",IF(AND(O3<>"",P3<>"",Q3<>""),"","입력누락"))
A4: =IF(COUNTA(B4:J4)=0,"",ROW()-1) | K4: =IF(COUNTA(B4:J4)=0,"",IF(R4<>"","확인필요(입력누락)",IF(COUNTIFS(보유목록!$I$2:$I$3001,"*"&P4&"*",보유목록!$I$2:$I$3001,"*"&Q4&"*",보유목록!$H$2:$H$3001,O4)>0,"있음",IF(COUNTIFS(보유목록!$I$2:$I$3001,"*"&P4&"*",보유목록!$I$2:$I$3001,"*"&Q4&"*")>0,"확인필요(연도다름)",IF(COUNTIFS(보유목록!$I$2:$I$3001,"*"&P4&"*",보유목록!$H$2:$H$3001,O4)>0,"확인필요(같은학교·같은연도)","없음"))))) | L4: =IF(OR(COUNTA(B4:J4)=0,R4<>""),"",COUNTIFS(보유목록!$I$2:$I$3001,"*"&P4&"*",보유목록!$I$2:$I$3001,"*"&Q4&"*")) | M4: =IF(OR(COUNTA(B4:J4)=0,R4<>""),"",IFERROR(LOOKUP(2,1/(ISNUMBER(SEARCH(P4,보유목록!$I$2:$I$3001))*ISNUMBER(SEARCH(Q4,보유목록!$I$2:$I$3001))*(보유목록!$H$2:$H$3001=O4)),보유목록!$B$2:$B$3001),IFERROR(LOOKUP(2,1/(ISNUMBER(SEARCH(P4,보유목록!$I$2:$I$3001))*ISNUMBER(SEARCH(Q4,보유목록!$I$2:$I$3001))),보유목록!$B$2:$B$3001),""))) | O4: =IFERROR(IF(AND(LEN(SUBSTITUTE(SUBSTITUTE(SUBSTITUTE(TRIM(C4&""),CHAR(160),"")," ",""),"년",""))=4,VALUE(SUBSTITUTE(SUBSTITUTE(SUBSTITUTE(TRIM(C4&""),CHAR(160),"")," ",""),"년",""))>=1900,VALUE(SUBSTITUTE(SUBSTITUTE(SUBSTITUTE(TRIM(C4&""),CHAR(160),"")," ",""),"년",""))<=2099,TEXT(VALUE(SUBSTITUTE(SUBSTITUTE(SUBSTITUTE(TRIM(C4&""),CHAR(160),"")," ",""),"년","")),"0000")=SUBSTITUTE(SUBSTITUTE(SUBSTITUTE(TRIM(C4&""),CHAR(160),"")," ",""),"년","")),SUBSTITUTE(SUBSTITUTE(SUBSTITUTE(TRIM(C4&""),CHAR(160),"")," ",""),"년",""),""),"") | P4: =SUBSTITUTE(SUBSTITUTE(SUBSTITUTE(SUBSTITUTE(SUBSTITUTE(SUBSTITUTE(SUBSTITUTE(SUBSTITUTE(TRIM(D4&""),CHAR(160),"")," ",""),"초등학교","초"),"중학교","중"),"고등학교","고"),"~","~~"),"*","~*"),"?","~?") | Q4: =SUBSTITUTE(SUBSTITUTE(SUBSTITUTE(SUBSTITUTE(SUBSTITUTE(SUBSTITUTE(SUBSTITUTE(SUBSTITUTE(TRIM(E4&""),CHAR(160),"")," ",""),"초등학교","초"),"중학교","중"),"고등학교","고"),"~","~~"),"*","~*"),"?","~?") | R4: =IF(COUNTA(B4:J4)=0,"",IF(AND(O4<>"",P4<>"",Q4<>""),"","입력누락"))
A5: =IF(COUNTA(B5:J5)=0,"",ROW()-1) | K5: =IF(COUNTA(B5:J5)=0,"",IF(R5<>"","확인필요(입력누락)",IF(COUNTIFS(보유목록!$I$2:$I$3001,"*"&P5&"*",보유목록!$I$2:$I$3001,"*"&Q5&"*",보유목록!$H$2:$H$3001,O5)>0,"있음",IF(COUNTIFS(보유목록!$I$2:$I$3001,"*"&P5&"*",보유목록!$I$2:$I$3001,"*"&Q5&"*")>0,"확인필요(연도다름)",IF(COUNTIFS(보유목록!$I$2:$I$3001,"*"&P5&"*",보유목록!$H$2:$H$3001,O5)>0,"확인필요(같은학교·같은연도)","없음"))))) | L5: =IF(OR(COUNTA(B5:J5)=0,R5<>""),"",COUNTIFS(보유목록!$I$2:$I$3001,"*"&P5&"*",보유목록!$I$2:$I$3001,"*"&Q5&"*")) | M5: =IF(OR(COUNTA(B5:J5)=0,R5<>""),"",IFERROR(LOOKUP(2,1/(ISNUMBER(SEARCH(P5,보유목록!$I$2:$I$3001))*ISNUMBER(SEARCH(Q5,보유목록!$I$2:$I$3001))*(보유목록!$H$2:$H$3001=O5)),보유목록!$B$2:$B$3001),IFERROR(LOOKUP(2,1/(ISNUMBER(SEARCH(P5,보유목록!$I$2:$I$3001))*ISNUMBER(SEARCH(Q5,보유목록!$I$2:$I$3001))),보유목록!$B$2:$B$3001),""))) | O5: =IFERROR(IF(AND(LEN(SUBSTITUTE(SUBSTITUTE(SUBSTITUTE(TRIM(C5&""),CHAR(160),"")," ",""),"년",""))=4,VALUE(SUBSTITUTE(SUBSTITUTE(SUBSTITUTE(TRIM(C5&""),CHAR(160),"")," ",""),"년",""))>=1900,VALUE(SUBSTITUTE(SUBSTITUTE(SUBSTITUTE(TRIM(C5&""),CHAR(160),"")," ",""),"년",""))<=2099,TEXT(VALUE(SUBSTITUTE(SUBSTITUTE(SUBSTITUTE(TRIM(C5&""),CHAR(160),"")," ",""),"년","")),"0000")=SUBSTITUTE(SUBSTITUTE(SUBSTITUTE(TRIM(C5&""),CHAR(160),"")," ",""),"년","")),SUBSTITUTE(SUBSTITUTE(SUBSTITUTE(TRIM(C5&""),CHAR(160),"")," ",""),"년",""),""),"") | P5: =SUBSTITUTE(SUBSTITUTE(SUBSTITUTE(SUBSTITUTE(SUBSTITUTE(SUBSTITUTE(SUBSTITUTE(SUBSTITUTE(TRIM(D5&""),CHAR(160),"")," ",""),"초등학교","초"),"중학교","중"),"고등학교","고"),"~","~~"),"*","~*"),"?","~?") | Q5: =SUBSTITUTE(SUBSTITUTE(SUBSTITUTE(SUBSTITUTE(SUBSTITUTE(SUBSTITUTE(SUBSTITUTE(SUBSTITUTE(TRIM(E5&""),CHAR(160),"")," ",""),"초등학교","초"),"중학교","중"),"고등학교","고"),"~","~~"),"*","~*"),"?","~?") | R5: =IF(COUNTA(B5:J5)=0,"",IF(AND(O5<>"",P5<>"",Q5<>""),"","입력누락"))
A6: =IF(COUNTA(B6:J6)=0,"",ROW()-1) | K6: =IF(COUNTA(B6:J6)=0,"",IF(R6<>"","확인필요(입력누락)",IF(COUNTIFS(보유목록!$I$2:$I$3001,"*"&P6&"*",보유목록!$I$2:$I$3001,"*"&Q6&"*",보유목록!$H$2:$H$3001,O6)>0,"있음",IF(COUNTIFS(보유목록!$I$2:$I$3001,"*"&P6&"*",보유목록!$I$2:$I$3001,"*"&Q6&"*")>0,"확인필요(연도다름)",IF(COUNTIFS(보유목록!$I$2:$I$3001,"*"&P6&"*",보유목록!$H$2:$H$3001,O6)>0,"확인필요(같은학교·같은연도)","없음"))))) | L6: =IF(OR(COUNTA(B6:J6)=0,R6<>""),"",COUNTIFS(보유목록!$I$2:$I$3001,"*"&P6&"*",보유목록!$I$2:$I$3001,"*"&Q6&"*")) | M6: =IF(OR(COUNTA(B6:J6)=0,R6<>""),"",IFERROR(LOOKUP(2,1/(ISNUMBER(SEARCH(P6,보유목록!$I$2:$I$3001))*ISNUMBER(SEARCH(Q6,보유목록!$I$2:$I$3001))*(보유목록!$H$2:$H$3001=O6)),보유목록!$B$2:$B$3001),IFERROR(LOOKUP(2,1/(ISNUMBER(SEARCH(P6,보유목록!$I$2:$I$3001))*ISNUMBER(SEARCH(Q6,보유목록!$I$2:$I$3001))),보유목록!$B$2:$B$3001),""))) | O6: =IFERROR(IF(AND(LEN(SUBSTITUTE(SUBSTITUTE(SUBSTITUTE(TRIM(C6&""),CHAR(160),"")," ",""),"년",""))=4,VALUE(SUBSTITUTE(SUBSTITUTE(SUBSTITUTE(TRIM(C6&""),CHAR(160),"")," ",""),"년",""))>=1900,VALUE(SUBSTITUTE(SUBSTITUTE(SUBSTITUTE(TRIM(C6&""),CHAR(160),"")," ",""),"년",""))<=2099,TEXT(VALUE(SUBSTITUTE(SUBSTITUTE(SUBSTITUTE(TRIM(C6&""),CHAR(160),"")," ",""),"년","")),"0000")=SUBSTITUTE(SUBSTITUTE(SUBSTITUTE(TRIM(C6&""),CHAR(160),"")," ",""),"년","")),SUBSTITUTE(SUBSTITUTE(SUBSTITUTE(TRIM(C6&""),CHAR(160),"")," ",""),"년",""),""),"") | P6: =SUBSTITUTE(SUBSTITUTE(SUBSTITUTE(SUBSTITUTE(SUBSTITUTE(SUBSTITUTE(SUBSTITUTE(SUBSTITUTE(TRIM(D6&""),CHAR(160),"")," ",""),"초등학교","초"),"중학교","중"),"고등학교","고"),"~","~~"),"*","~*"),"?","~?") | Q6: =SUBSTITUTE(SUBSTITUTE(SUBSTITUTE(SUBSTITUTE(SUBSTITUTE(SUBSTITUTE(SUBSTITUTE(SUBSTITUTE(TRIM(E6&""),CHAR(160),"")," ",""),"초등학교","초"),"중학교","중"),"고등학교","고"),"~","~~"),"*","~*"),"?","~?") | R6: =IF(COUNTA(B6:J6)=0,"",IF(AND(O6<>"",P6<>"",Q6<>""),"","입력누락"))
A7: =IF(COUNTA(B7:J7)=0,"",ROW()-1) | K7: =IF(COUNTA(B7:J7)=0,"",IF(R7<>"","확인필요(입력누락)",IF(COUNTIFS(보유목록!$I$2:$I$3001,"*"&P7&"*",보유목록!$I$2:$I$3001,"*"&Q7&"*",보유목록!$H$2:$H$3001,O7)>0,"있음",IF(COUNTIFS(보유목록!$I$2:$I$3001,"*"&P7&"*",보유목록!$I$2:$I$3001,"*"&Q7&"*")>0,"확인필요(연도다름)",IF(COUNTIFS(보유목록!$I$2:$I$3001,"*"&P7&"*",보유목록!$H$2:$H$3001,O7)>0,"확인필요(같은학교·같은연도)","없음"))))) | L7: =IF(OR(COUNTA(B7:J7)=0,R7<>""),"",COUNTIFS(보유목록!$I$2:$I$3001,"*"&P7&"*",보유목록!$I$2:$I$3001,"*"&Q7&"*")) | M7: =IF(OR(COUNTA(B7:J7)=0,R7<>""),"",IFERROR(LOOKUP(2,1/(ISNUMBER(SEARCH(P7,보유목록!$I$2:$I$3001))*ISNUMBER(SEARCH(Q7,보유목록!$I$2:$I$3001))*(보유목록!$H$2:$H$3001=O7)),보유목록!$B$2:$B$3001),IFERROR(LOOKUP(2,1/(ISNUMBER(SEARCH(P7,보유목록!$I$2:$I$3001))*ISNUMBER(SEARCH(Q7,보유목록!$I$2:$I$3001))),보유목록!$B$2:$B$3001),""))) | O7: =IFERROR(IF(AND(LEN(SUBSTITUTE(SUBSTITUTE(SUBSTITUTE(TRIM(C7&""),CHAR(160),"")," ",""),"년",""))=4,VALUE(SUBSTITUTE(SUBSTITUTE(SUBSTITUTE(TRIM(C7&""),CHAR(160),"")," ",""),"년",""))>=1900,VALUE(SUBSTITUTE(SUBSTITUTE(SUBSTITUTE(TRIM(C7&""),CHAR(160),"")," ",""),"년",""))<=2099,TEXT(VALUE(SUBSTITUTE(SUBSTITUTE(SUBSTITUTE(TRIM(C7&""),CHAR(160),"")," ",""),"년","")),"0000")=SUBSTITUTE(SUBSTITUTE(SUBSTITUTE(TRIM(C7&""),CHAR(160),"")," ",""),"년","")),SUBSTITUTE(SUBSTITUTE(SUBSTITUTE(TRIM(C7&""),CHAR(160),"")," ",""),"년",""),""),"") | P7: =SUBSTITUTE(SUBSTITUTE(SUBSTITUTE(SUBSTITUTE(SUBSTITUTE(SUBSTITUTE(SUBSTITUTE(SUBSTITUTE(TRIM(D7&""),CHAR(160),"")," ",""),"초등학교","초"),"중학교","중"),"고등학교","고"),"~","~~"),"*","~*"),"?","~?") | Q7: =SUBSTITUTE(SUBSTITUTE(SUBSTITUTE(SUBSTITUTE(SUBSTITUTE(SUBSTITUTE(SUBSTITUTE(SUBSTITUTE(TRIM(E7&""),CHAR(160),"")," ",""),"초등학교","초"),"중학교","중"),"고등학교","고"),"~","~~"),"*","~*"),"?","~?") | R7: =IF(COUNTA(B7:J7)=0,"",IF(AND(O7<>"",P7<>"",Q7<>""),"","입력누락"))
A8: =IF(COUNTA(B8:J8)=0,"",ROW()-1) | K8: =IF(COUNTA(B8:J8)=0,"",IF(R8<>"","확인필요(입력누락)",IF(COUNTIFS(보유목록!$I$2:$I$3001,"*"&P8&"*",보유목록!$I$2:$I$3001,"*"&Q8&"*",보유목록!$H$2:$H$3001,O8)>0,"있음",IF(COUNTIFS(보유목록!$I$2:$I$3001,"*"&P8&"*",보유목록!$I$2:$I$3001,"*"&Q8&"*")>0,"확인필요(연도다름)",IF(COUNTIFS(보유목록!$I$2:$I$3001,"*"&P8&"*",보유목록!$H$2:$H$3001,O8)>0,"확인필요(같은학교·같은연도)","없음"))))) | L8: =IF(OR(COUNTA(B8:J8)=0,R8<>""),"",COUNTIFS(보유목록!$I$2:$I$3001,"*"&P8&"*",보유목록!$I$2:$I$3001,"*"&Q8&"*")) | M8: =IF(OR(COUNTA(B8:J8)=0,R8<>""),"",IFERROR(LOOKUP(2,1/(ISNUMBER(SEARCH(P8,보유목록!$I$2:$I$3001))*ISNUMBER(SEARCH(Q8,보유목록!$I$2:$I$3001))*(보유목록!$H$2:$H$3001=O8)),보유목록!$B$2:$B$3001),IFERROR(LOOKUP(2,1/(ISNUMBER(SEARCH(P8,보유목록!$I$2:$I$3001))*ISNUMBER(SEARCH(Q8,보유목록!$I$2:$I$3001))),보유목록!$B$2:$B$3001),""))) | O8: =IFERROR(IF(AND(LEN(SUBSTITUTE(SUBSTITUTE(SUBSTITUTE(TRIM(C8&""),CHAR(160),"")," ",""),"년",""))=4,VALUE(SUBSTITUTE(SUBSTITUTE(SUBSTITUTE(TRIM(C8&""),CHAR(160),"")," ",""),"년",""))>=1900,VALUE(SUBSTITUTE(SUBSTITUTE(SUBSTITUTE(TRIM(C8&""),CHAR(160),"")," ",""),"년",""))<=2099,TEXT(VALUE(SUBSTITUTE(SUBSTITUTE(SUBSTITUTE(TRIM(C8&""),CHAR(160),"")," ",""),"년","")),"0000")=SUBSTITUTE(SUBSTITUTE(SUBSTITUTE(TRIM(C8&""),CHAR(160),"")," ",""),"년","")),SUBSTITUTE(SUBSTITUTE(SUBSTITUTE(TRIM(C8&""),CHAR(160),"")," ",""),"년",""),""),"") | P8: =SUBSTITUTE(SUBSTITUTE(SUBSTITUTE(SUBSTITUTE(SUBSTITUTE(SUBSTITUTE(SUBSTITUTE(SUBSTITUTE(TRIM(D8&""),CHAR(160),"")," ",""),"초등학교","초"),"중학교","중"),"고등학교","고"),"~","~~"),"*","~*"),"?","~?") | Q8: =SUBSTITUTE(SUBSTITUTE(SUBSTITUTE(SUBSTITUTE(SUBSTITUTE(SUBSTITUTE(SUBSTITUTE(SUBSTITUTE(TRIM(E8&""),CHAR(160),"")," ",""),"초등학교","초"),"중학교","중"),"고등학교","고"),"~","~~"),"*","~*"),"?","~?") | R8: =IF(COUNTA(B8:J8)=0,"",IF(AND(O8<>"",P8<>"",Q8<>""),"","입력누락"))
A9: =IF(COUNTA(B9:J9)=0,"",ROW()-1) | K9: =IF(COUNTA(B9:J9)=0,"",IF(R9<>"","확인필요(입력누락)",IF(COUNTIFS(보유목록!$I$2:$I$3001,"*"&P9&"*",보유목록!$I$2:$I$3001,"*"&Q9&"*",보유목록!$H$2:$H$3001,O9)>0,"있음",IF(COUNTIFS(보유목록!$I$2:$I$3001,"*"&P9&"*",보유목록!$I$2:$I$3001,"*"&Q9&"*")>0,"확인필요(연도다름)",IF(COUNTIFS(보유목록!$I$2:$I$3001,"*"&P9&"*",보유목록!$H$2:$H$3001,O9)>0,"확인필요(같은학교·같은연도)","없음"))))) | L9: =IF(OR(COUNTA(B9:J9)=0,R9<>""),"",COUNTIFS(보유목록!$I$2:$I$3001,"*"&P9&"*",보유목록!$I$2:$I$3001,"*"&Q9&"*")) | M9: =IF(OR(COUNTA(B9:J9)=0,R9<>""),"",IFERROR(LOOKUP(2,1/(ISNUMBER(SEARCH(P9,보유목록!$I$2:$I$3001))*ISNUMBER(SEARCH(Q9,보유목록!$I$2:$I$3001))*(보유목록!$H$2:$H$3001=O9)),보유목록!$B$2:$B$3001),IFERROR(LOOKUP(2,1/(ISNUMBER(SEARCH(P9,보유목록!$I$2:$I$3001))*ISNUMBER(SEARCH(Q9,보유목록!$I$2:$I$3001))),보유목록!$B$2:$B$3001),""))) | O9: =IFERROR(IF(AND(LEN(SUBSTITUTE(SUBSTITUTE(SUBSTITUTE(TRIM(C9&""),CHAR(160),"")," ",""),"년",""))=4,VALUE(SUBSTITUTE(SUBSTITUTE(SUBSTITUTE(TRIM(C9&""),CHAR(160),"")," ",""),"년",""))>=1900,VALUE(SUBSTITUTE(SUBSTITUTE(SUBSTITUTE(TRIM(C9&""),CHAR(160),"")," ",""),"년",""))<=2099,TEXT(VALUE(SUBSTITUTE(SUBSTITUTE(SUBSTITUTE(TRIM(C9&""),CHAR(160),"")," ",""),"년","")),"0000")=SUBSTITUTE(SUBSTITUTE(SUBSTITUTE(TRIM(C9&""),CHAR(160),"")," ",""),"년","")),SUBSTITUTE(SUBSTITUTE(SUBSTITUTE(TRIM(C9&""),CHAR(160),"")," ",""),"년",""),""),"") | P9: =SUBSTITUTE(SUBSTITUTE(SUBSTITUTE(SUBSTITUTE(SUBSTITUTE(SUBSTITUTE(SUBSTITUTE(SUBSTITUTE(TRIM(D9&""),CHAR(160),"")," ",""),"초등학교","초"),"중학교","중"),"고등학교","고"),"~","~~"),"*","~*"),"?","~?") | Q9: =SUBSTITUTE(SUBSTITUTE(SUBSTITUTE(SUBSTITUTE(SUBSTITUTE(SUBSTITUTE(SUBSTITUTE(SUBSTITUTE(TRIM(E9&""),CHAR(160),"")," ",""),"초등학교","초"),"중학교","중"),"고등학교","고"),"~","~~"),"*","~*"),"?","~?") | R9: =IF(COUNTA(B9:J9)=0,"",IF(AND(O9<>"",P9<>"",Q9<>""),"","입력누락"))
A10: =IF(COUNTA(B10:J10)=0,"",ROW()-1) | K10: =IF(COUNTA(B10:J10)=0,"",IF(R10<>"","확인필요(입력누락)",IF(COUNTIFS(보유목록!$I$2:$I$3001,"*"&P10&"*",보유목록!$I$2:$I$3001,"*"&Q10&"*",보유목록!$H$2:$H$3001,O10)>0,"있음",IF(COUNTIFS(보유목록!$I$2:$I$3001,"*"&P10&"*",보유목록!$I$2:$I$3001,"*"&Q10&"*")>0,"확인필요(연도다름)",IF(COUNTIFS(보유목록!$I$2:$I$3001,"*"&P10&"*",보유목록!$H$2:$H$3001,O10)>0,"확인필요(같은학교·같은연도)","없음"))))) | L10: =IF(OR(COUNTA(B10:J10)=0,R10<>""),"",COUNTIFS(보유목록!$I$2:$I$3001,"*"&P10&"*",보유목록!$I$2:$I$3001,"*"&Q10&"*")) | M10: =IF(OR(COUNTA(B10:J10)=0,R10<>""),"",IFERROR(LOOKUP(2,1/(ISNUMBER(SEARCH(P10,보유목록!$I$2:$I$3001))*ISNUMBER(SEARCH(Q10,보유목록!$I$2:$I$3001))*(보유목록!$H$2:$H$3001=O10)),보유목록!$B$2:$B$3001),IFERROR(LOOKUP(2,1/(ISNUMBER(SEARCH(P10,보유목록!$I$2:$I$3001))*ISNUMBER(SEARCH(Q10,보유목록!$I$2:$I$3001))),보유목록!$B$2:$B$3001),""))) | O10: =IFERROR(IF(AND(LEN(SUBSTITUTE(SUBSTITUTE(SUBSTITUTE(TRIM(C10&""),CHAR(160),"")," ",""),"년",""))=4,VALUE(SUBSTITUTE(SUBSTITUTE(SUBSTITUTE(TRIM(C10&""),CHAR(160),"")," ",""),"년",""))>=1900,VALUE(SUBSTITUTE(SUBSTITUTE(SUBSTITUTE(TRIM(C10&""),CHAR(160),"")," ",""),"년",""))<=2099,TEXT(VALUE(SUBSTITUTE(SUBSTITUTE(SUBSTITUTE(TRIM(C10&""),CHAR(160),"")," ",""),"년","")),"0000")=SUBSTITUTE(SUBSTITUTE(SUBSTITUTE(TRIM(C10&""),CHAR(160),"")," ",""),"년","")),SUBSTITUTE(SUBSTITUTE(SUBSTITUTE(TRIM(C10&""),CHAR(160),"")," ",""),"년",""),""),"") | P10: =SUBSTITUTE(SUBSTITUTE(SUBSTITUTE(SUBSTITUTE(SUBSTITUTE(SUBSTITUTE(SUBSTITUTE(SUBSTITUTE(TRIM(D10&""),CHAR(160),"")," ",""),"초등학교","초"),"중학교","중"),"고등학교","고"),"~","~~"),"*","~*"),"?","~?") | Q10: =SUBSTITUTE(SUBSTITUTE(SUBSTITUTE(SUBSTITUTE(SUBSTITUTE(SUBSTITUTE(SUBSTITUTE(SUBSTITUTE(TRIM(E10&""),CHAR(160),"")," ",""),"초등학교","초"),"중학교","중"),"고등학교","고"),"~","~~"),"*","~*"),"?","~?") | R10: =IF(COUNTA(B10:J10)=0,"",IF(AND(O10<>"",P10<>"",Q10<>""),"","입력누락"))
A11: =IF(COUNTA(B11:J11)=0,"",ROW()-1) | K11: =IF(COUNTA(B11:J11)=0,"",IF(R11<>"","확인필요(입력누락)",IF(COUNTIFS(보유목록!$I$2:$I$3001,"*"&P11&"*",보유목록!$I$2:$I$3001,"*"&Q11&"*",보유목록!$H$2:$H$3001,O11)>0,"있음",IF(COUNTIFS(보유목록!$I$2:$I$3001,"*"&P11&"*",보유목록!$I$2:$I$3001,"*"&Q11&"*")>0,"확인필요(연도다름)",IF(COUNTIFS(보유목록!$I$2:$I$3001,"*"&P11&"*",보유목록!$H$2:$H$3001,O11)>0,"확인필요(같은학교·같은연도)","없음"))))) | L11: =IF(OR(COUNTA(B11:J11)=0,R11<>""),"",COUNTIFS(보유목록!$I$2:$I$3001,"*"&P11&"*",보유목록!$I$2:$I$3001,"*"&Q11&"*")) | M11: =IF(OR(COUNTA(B11:J11)=0,R11<>""),"",IFERROR(LOOKUP(2,1/(ISNUMBER(SEARCH(P11,보유목록!$I$2:$I$3001))*ISNUMBER(SEARCH(Q11,보유목록!$I$2:$I$3001))*(보유목록!$H$2:$H$3001=O11)),보유목록!$B$2:$B$3001),IFERROR(LOOKUP(2,1/(ISNUMBER(SEARCH(P11,보유목록!$I$2:$I$3001))*ISNUMBER(SEARCH(Q11,보유목록!$I$2:$I$3001))),보유목록!$B$2:$B$3001),""))) | O11: =IFERROR(IF(AND(LEN(SUBSTITUTE(SUBSTITUTE(SUBSTITUTE(TRIM(C11&""),CHAR(160),"")," ",""),"년",""))=4,VALUE(SUBSTITUTE(SUBSTITUTE(SUBSTITUTE(TRIM(C11&""),CHAR(160),"")," ",""),"년",""))>=1900,VALUE(SUBSTITUTE(SUBSTITUTE(SUBSTITUTE(TRIM(C11&""),CHAR(160),"")," ",""),"년",""))<=2099,TEXT(VALUE(SUBSTITUTE(SUBSTITUTE(SUBSTITUTE(TRIM(C11&""),CHAR(160),"")," ",""),"년","")),"0000")=SUBSTITUTE(SUBSTITUTE(SUBSTITUTE(TRIM(C11&""),CHAR(160),"")," ",""),"년","")),SUBSTITUTE(SUBSTITUTE(SUBSTITUTE(TRIM(C11&""),CHAR(160),"")," ",""),"년",""),""),"") | P11: =SUBSTITUTE(SUBSTITUTE(SUBSTITUTE(SUBSTITUTE(SUBSTITUTE(SUBSTITUTE(SUBSTITUTE(SUBSTITUTE(TRIM(D11&""),CHAR(160),"")," ",""),"초등학교","초"),"중학교","중"),"고등학교","고"),"~","~~"),"*","~*"),"?","~?") | Q11: =SUBSTITUTE(SUBSTITUTE(SUBSTITUTE(SUBSTITUTE(SUBSTITUTE(SUBSTITUTE(SUBSTITUTE(SUBSTITUTE(TRIM(E11&""),CHAR(160),"")," ",""),"초등학교","초"),"중학교","중"),"고등학교","고"),"~","~~"),"*","~*"),"?","~?") | R11: =IF(COUNTA(B11:J11)=0,"",IF(AND(O11<>"",P11<>"",Q11<>""),"","입력누락"))
A12: =IF(COUNTA(B12:J12)=0,"",ROW()-1) | K12: =IF(COUNTA(B12:J12)=0,"",IF(R12<>"","확인필요(입력누락)",IF(COUNTIFS(보유목록!$I$2:$I$3001,"*"&P12&"*",보유목록!$I$2:$I$3001,"*"&Q12&"*",보유목록!$H$2:$H$3001,O12)>0,"있음",IF(COUNTIFS(보유목록!$I$2:$I$3001,"*"&P12&"*",보유목록!$I$2:$I$3001,"*"&Q12&"*")>0,"확인필요(연도다름)",IF(COUNTIFS(보유목록!$I$2:$I$3001,"*"&P12&"*",보유목록!$H$2:$H$3001,O12)>0,"확인필요(같은학교·같은연도)","없음"))))) | L12: =IF(OR(COUNTA(B12:J12)=0,R12<>""),"",COUNTIFS(보유목록!$I$2:$I$3001,"*"&P12&"*",보유목록!$I$2:$I$3001,"*"&Q12&"*")) | M12: =IF(OR(COUNTA(B12:J12)=0,R12<>""),"",IFERROR(LOOKUP(2,1/(ISNUMBER(SEARCH(P12,보유목록!$I$2:$I$3001))*ISNUMBER(SEARCH(Q12,보유목록!$I$2:$I$3001))*(보유목록!$H$2:$H$3001=O12)),보유목록!$B$2:$B$3001),IFERROR(LOOKUP(2,1/(ISNUMBER(SEARCH(P12,보유목록!$I$2:$I$3001))*ISNUMBER(SEARCH(Q12,보유목록!$I$2:$I$3001))),보유목록!$B$2:$B$3001),""))) | O12: =IFERROR(IF(AND(LEN(SUBSTITUTE(SUBSTITUTE(SUBSTITUTE(TRIM(C12&""),CHAR(160),"")," ",""),"년",""))=4,VALUE(SUBSTITUTE(SUBSTITUTE(SUBSTITUTE(TRIM(C12&""),CHAR(160),"")," ",""),"년",""))>=1900,VALUE(SUBSTITUTE(SUBSTITUTE(SUBSTITUTE(TRIM(C12&""),CHAR(160),"")," ",""),"년",""))<=2099,TEXT(VALUE(SUBSTITUTE(SUBSTITUTE(SUBSTITUTE(TRIM(C12&""),CHAR(160),"")," ",""),"년","")),"0000")=SUBSTITUTE(SUBSTITUTE(SUBSTITUTE(TRIM(C12&""),CHAR(160),"")," ",""),"년","")),SUBSTITUTE(SUBSTITUTE(SUBSTITUTE(TRIM(C12&""),CHAR(160),"")," ",""),"년",""),""),"") | P12: =SUBSTITUTE(SUBSTITUTE(SUBSTITUTE(SUBSTITUTE(SUBSTITUTE(SUBSTITUTE(SUBSTITUTE(SUBSTITUTE(TRIM(D12&""),CHAR(160),"")," ",""),"초등학교","초"),"중학교","중"),"고등학교","고"),"~","~~"),"*","~*"),"?","~?") | Q12: =SUBSTITUTE(SUBSTITUTE(SUBSTITUTE(SUBSTITUTE(SUBSTITUTE(SUBSTITUTE(SUBSTITUTE(SUBSTITUTE(TRIM(E12&""),CHAR(160),"")," ",""),"초등학교","초"),"중학교","중"),"고등학교","고"),"~","~~"),"*","~*"),"?","~?") | R12: =IF(COUNTA(B12:J12)=0,"",IF(AND(O12<>"",P12<>"",Q12<>""),"","입력누락"))
A13: =IF(COUNTA(B13:J13)=0,"",ROW()-1) | K13: =IF(COUNTA(B13:J13)=0,"",IF(R13<>"","확인필요(입력누락)",IF(COUNTIFS(보유목록!$I$2:$I$3001,"*"&P13&"*",보유목록!$I$2:$I$3001,"*"&Q13&"*",보유목록!$H$2:$H$3001,O13)>0,"있음",IF(COUNTIFS(보유목록!$I$2:$I$3001,"*"&P13&"*",보유목록!$I$2:$I$3001,"*"&Q13&"*")>0,"확인필요(연도다름)",IF(COUNTIFS(보유목록!$I$2:$I$3001,"*"&P13&"*",보유목록!$H$2:$H$3001,O13)>0,"확인필요(같은학교·같은연도)","없음"))))) | L13: =IF(OR(COUNTA(B13:J13)=0,R13<>""),"",COUNTIFS(보유목록!$I$2:$I$3001,"*"&P13&"*",보유목록!$I$2:$I$3001,"*"&Q13&"*")) | M13: =IF(OR(COUNTA(B13:J13)=0,R13<>""),"",IFERROR(LOOKUP(2,1/(ISNUMBER(SEARCH(P13,보유목록!$I$2:$I$3001))*ISNUMBER(SEARCH(Q13,보유목록!$I$2:$I$3001))*(보유목록!$H$2:$H$3001=O13)),보유목록!$B$2:$B$3001),IFERROR(LOOKUP(2,1/(ISNUMBER(SEARCH(P13,보유목록!$I$2:$I$3001))*ISNUMBER(SEARCH(Q13,보유목록!$I$2:$I$3001))),보유목록!$B$2:$B$3001),""))) | O13: =IFERROR(IF(AND(LEN(SUBSTITUTE(SUBSTITUTE(SUBSTITUTE(TRIM(C13&""),CHAR(160),"")," ",""),"년",""))=4,VALUE(SUBSTITUTE(SUBSTITUTE(SUBSTITUTE(TRIM(C13&""),CHAR(160),"")," ",""),"년",""))>=1900,VALUE(SUBSTITUTE(SUBSTITUTE(SUBSTITUTE(TRIM(C13&""),CHAR(160),"")," ",""),"년",""))<=2099,TEXT(VALUE(SUBSTITUTE(SUBSTITUTE(SUBSTITUTE(TRIM(C13&""),CHAR(160),"")," ",""),"년","")),"0000")=SUBSTITUTE(SUBSTITUTE(SUBSTITUTE(TRIM(C13&""),CHAR(160),"")," ",""),"년","")),SUBSTITUTE(SUBSTITUTE(SUBSTITUTE(TRIM(C13&""),CHAR(160),"")," ",""),"년",""),""),"") | P13: =SUBSTITUTE(SUBSTITUTE(SUBSTITUTE(SUBSTITUTE(SUBSTITUTE(SUBSTITUTE(SUBSTITUTE(SUBSTITUTE(TRIM(D13&""),CHAR(160),"")," ",""),"초등학교","초"),"중학교","중"),"고등학교","고"),"~","~~"),"*","~*"),"?","~?") | Q13: =SUBSTITUTE(SUBSTITUTE(SUBSTITUTE(SUBSTITUTE(SUBSTITUTE(SUBSTITUTE(SUBSTITUTE(SUBSTITUTE(TRIM(E13&""),CHAR(160),"")," ",""),"초등학교","초"),"중학교","중"),"고등학교","고"),"~","~~"),"*","~*"),"?","~?") | R13: =IF(COUNTA(B13:J13)=0,"",IF(AND(O13<>"",P13<>"",Q13<>""),"","입력누락"))
A14: =IF(COUNTA(B14:J14)=0,"",ROW()-1) | K14: =IF(COUNTA(B14:J14)=0,"",IF(R14<>"","확인필요(입력누락)",IF(COUNTIFS(보유목록!$I$2:$I$3001,"*"&P14&"*",보유목록!$I$2:$I$3001,"*"&Q14&"*",보유목록!$H$2:$H$3001,O14)>0,"있음",IF(COUNTIFS(보유목록!$I$2:$I$3001,"*"&P14&"*",보유목록!$I$2:$I$3001,"*"&Q14&"*")>0,"확인필요(연도다름)",IF(COUNTIFS(보유목록!$I$2:$I$3001,"*"&P14&"*",보유목록!$H$2:$H$3001,O14)>0,"확인필요(같은학교·같은연도)","없음"))))) | L14: =IF(OR(COUNTA(B14:J14)=0,R14<>""),"",COUNTIFS(보유목록!$I$2:$I$3001,"*"&P14&"*",보유목록!$I$2:$I$3001,"*"&Q14&"*")) | M14: =IF(OR(COUNTA(B14:J14)=0,R14<>""),"",IFERROR(LOOKUP(2,1/(ISNUMBER(SEARCH(P14,보유목록!$I$2:$I$3001))*ISNUMBER(SEARCH(Q14,보유목록!$I$2:$I$3001))*(보유목록!$H$2:$H$3001=O14)),보유목록!$B$2:$B$3001),IFERROR(LOOKUP(2,1/(ISNUMBER(SEARCH(P14,보유목록!$I$2:$I$3001))*ISNUMBER(SEARCH(Q14,보유목록!$I$2:$I$3001))),보유목록!$B$2:$B$3001),""))) | O14: =IFERROR(IF(AND(LEN(SUBSTITUTE(SUBSTITUTE(SUBSTITUTE(TRIM(C14&""),CHAR(160),"")," ",""),"년",""))=4,VALUE(SUBSTITUTE(SUBSTITUTE(SUBSTITUTE(TRIM(C14&""),CHAR(160),"")," ",""),"년",""))>=1900,VALUE(SUBSTITUTE(SUBSTITUTE(SUBSTITUTE(TRIM(C14&""),CHAR(160),"")," ",""),"년",""))<=2099,TEXT(VALUE(SUBSTITUTE(SUBSTITUTE(SUBSTITUTE(TRIM(C14&""),CHAR(160),"")," ",""),"년","")),"0000")=SUBSTITUTE(SUBSTITUTE(SUBSTITUTE(TRIM(C14&""),CHAR(160),"")," ",""),"년","")),SUBSTITUTE(SUBSTITUTE(SUBSTITUTE(TRIM(C14&""),CHAR(160),"")," ",""),"년",""),""),"") | P14: =SUBSTITUTE(SUBSTITUTE(SUBSTITUTE(SUBSTITUTE(SUBSTITUTE(SUBSTITUTE(SUBSTITUTE(SUBSTITUTE(TRIM(D14&""),CHAR(160),"")," ",""),"초등학교","초"),"중학교","중"),"고등학교","고"),"~","~~"),"*","~*"),"?","~?") | Q14: =SUBSTITUTE(SUBSTITUTE(SUBSTITUTE(SUBSTITUTE(SUBSTITUTE(SUBSTITUTE(SUBSTITUTE(SUBSTITUTE(TRIM(E14&""),CHAR(160),"")," ",""),"초등학교","초"),"중학교","중"),"고등학교","고"),"~","~~"),"*","~*"),"?","~?") | R14: =IF(COUNTA(B14:J14)=0,"",IF(AND(O14<>"",P14<>"",Q14<>""),"","입력누락"))
... A1001: =IF(COUNTA(B1001:J1001)=0,"",ROW()-1) | K1001: =IF(COUNTA(B1001:J1001)=0,"",IF(R1001<>"","확인필요(입력누락)",IF(COUNTIFS(보유목록!$I$2:$I$3001,"*"&P1001&"*",보유목록!$I$2:$I$3001,"*"&Q1001&"*",보유목록!$H$2:$H$3001,O1001)>0,"있음",IF(COUNTIFS(보유목록!$I$2:$I$3001,"*"&P1001&"*",보유목록!$I$2:$I$3001,"*"&Q1001&"*")>0,"확인필요(연도다름)",IF(COUNTIFS(보유목록!$I$2:$I$3001,"*"&P1001&"*",보유목록!$H$2:$H$3001,O1001)>0,"확인필요(같은학교·같은연도)","없음"))))) | L1001: =IF(OR(COUNTA(B1001:J1001)=0,R1001<>""),"",COUNTIFS(보유목록!$I$2:$I$3001,"*"&P1001&"*",보유목록!$I$2:$I$3001,"*"&Q1001&"*")) | M1001: =IF(OR(COUNTA(B1001:J1001)=0,R1001<>""),"",IFERROR(LOOKUP(2,1/(ISNUMBER(SEARCH(P1001,보유목록!$I$2:$I$3001))*ISNUMBER(SEARCH(Q1001,보유목록!$I$2:$I$3001))*(보유목록!$H$2:$H$3001=O1001)),보유목록!$B$2:$B$3001),IFERROR(LOOKUP(2,1/(ISNUMBER(SEARCH(P1001,보유목록!$I$2:$I$3001))*ISNUMBER(SEARCH(Q1001,보유목록!$I$2:$I$3001))),보유목록!$B$2:$B$3001),""))) | O1001: =IFERROR(IF(AND(LEN(SUBSTITUTE(SUBSTITUTE(SUBSTITUTE(TRIM(C1001&""),CHAR(160),"")," ",""),"년",""))=4,VALUE(SUBSTITUTE(SUBSTITUTE(SUBSTITUTE(TRIM(C1001&""),CHAR(160),"")," ",""),"년",""))>=1900,VALUE(SUBSTITUTE(SUBSTITUTE(SUBSTITUTE(TRIM(C1001&""),CHAR(160),"")," ",""),"년",""))<=2099,TEXT(VALUE(SUBSTITUTE(SUBSTITUTE(SUBSTITUTE(TRIM(C1001&""),CHAR(160),"")," ",""),"년","")),"0000")=SUBSTITUTE(SUBSTITUTE(SUBSTITUTE(TRIM(C1001&""),CHAR(160),"")," ",""),"년","")),SUBSTITUTE(SUBSTITUTE(SUBSTITUTE(TRIM(C1001&""),CHAR(160),"")," ",""),"년",""),""),"") | P1001: =SUBSTITUTE(SUBSTITUTE(SUBSTITUTE(SUBSTITUTE(SUBSTITUTE(SUBSTITUTE(SUBSTITUTE(SUBSTITUTE(TRIM(D1001&""),CHAR(160),"")," ",""),"초등학교","초"),"중학교","중"),"고등학교","고"),"~","~~"),"*","~*"),"?","~?") | Q1001: =SUBSTITUTE(SUBSTITUTE(SUBSTITUTE(SUBSTITUTE(SUBSTITUTE(SUBSTITUTE(SUBSTITUTE(SUBSTITUTE(TRIM(E1001&""),CHAR(160),"")," ",""),"초등학교","초"),"중학교","중"),"고등학교","고"),"~","~~"),"*","~*"),"?","~?") | R1001: =IF(COUNTA(B1001:J1001)=0,"",IF(AND(O1001<>"",P1001<>"",Q1001<>""),"","입력누락"))

Sheet 위치별요약
A1: 보관위치 | B1: 전체(권수) | C1: 있음 | D1: 확인필요 | E1: 없음 | F1: → 폐기후보 | G1: → 보관 | H1: → 등록요청 | I1: → 확인필요 | J1: 처리구분 미정
A2: =IF(설정!A2="","",설정!A2) -> 사무실 캐비닛A | B2: =IF($A2="","",SUMIFS(실물목록!$H$2:$H$1001,실물목록!$B$2:$B$1001,$A2)) | C2: =IF($A2="","",SUMIFS(실물목록!$H$2:$H$1001,실물목록!$B$2:$B$1001,$A2,실물목록!$K$2:$K$1001,"있음")) -> 1 | D2: =IF($A2="","",SUMIFS(실물목록!$H$2:$H$1001,실물목록!$B$2:$B$1001,$A2,실물목록!$K$2:$K$1001,"확인필요*")) -> 0 | E2: =IF($A2="","",SUMIFS(실물목록!$H$2:$H$1001,실물목록!$B$2:$B$1001,$A2,실물목록!$K$2:$K$1001,"없음")) -> 0 | F2: =IF($A2="","",SUMIFS(실물목록!$H$2:$H$1001,실물목록!$B$2:$B$1001,$A2,실물목록!$N$2:$N$1001,"폐기후보")) -> 1 | G2: =IF($A2="","",SUMIFS(실물목록!$H$2:$H$1001,실물목록!$B$2:$B$1001,$A2,실물목록!$N$2:$N$1001,"보관")) -> 0 | H2: =IF($A2="","",SUMIFS(실물목록!$H$2:$H$1001,실물목록!$B$2:$B$1001,$A2,실물목록!$N$2:$N$1001,"등록요청")) -> 0 | I2: =IF($A2="","",SUMIFS(실물목록!$H$2:$H$1001,실물목록!$B$2:$B$1001,$A2,실물목록!$N$2:$N$1001,"확인필요")) -> 0 | J2: =IF($A2="","",SUMIFS(실물목록!$H$2:$H$1001,실물목록!$B$2:$B$1001,$A2,실물목록!$K$2:$K$1001,"<>",실물목록!$N$2:$N$1001,""))
A3: =IF(설정!A3="","",설정!A3) -> 사무실 캐비닛B | B3: =IF($A3="","",SUMIFS(실물목록!$H$2:$H$1001,실물목록!$B$2:$B$1001,$A3)) | C3: =IF($A3="","",SUMIFS(실물목록!$H$2:$H$1001,실물목록!$B$2:$B$1001,$A3,실물목록!$K$2:$K$1001,"있음")) -> 0 | D3: =IF($A3="","",SUMIFS(실물목록!$H$2:$H$1001,실물목록!$B$2:$B$1001,$A3,실물목록!$K$2:$K$1001,"확인필요*")) -> 0 | E3: =IF($A3="","",SUMIFS(실물목록!$H$2:$H$1001,실물목록!$B$2:$B$1001,$A3,실물목록!$K$2:$K$1001,"없음")) -> 0 | F3: =IF($A3="","",SUMIFS(실물목록!$H$2:$H$1001,실물목록!$B$2:$B$1001,$A3,실물목록!$N$2:$N$1001,"폐기후보")) -> 0 | G3: =IF($A3="","",SUMIFS(실물목록!$H$2:$H$1001,실물목록!$B$2:$B$1001,$A3,실물목록!$N$2:$N$1001,"보관")) -> 0 | H3: =IF($A3="","",SUMIFS(실물목록!$H$2:$H$1001,실물목록!$B$2:$B$1001,$A3,실물목록!$N$2:$N$1001,"등록요청")) -> 0 | I3: =IF($A3="","",SUMIFS(실물목록!$H$2:$H$1001,실물목록!$B$2:$B$1001,$A3,실물목록!$N$2:$N$1001,"확인필요")) -> 0 | J3: =IF($A3="","",SUMIFS(실물목록!$H$2:$H$1001,실물목록!$B$2:$B$1001,$A3,실물목록!$K$2:$K$1001,"<>",실물목록!$N$2:$N$1001,""))
A4: =IF(설정!A4="","",설정!A4) -> 서고 1번 선반 | B4: =IF($A4="","",SUMIFS(실물목록!$H$2:$H$1001,실물목록!$B$2:$B$1001,$A4)) | C4: =IF($A4="","",SUMIFS(실물목록!$H$2:$H$1001,실물목록!$B$2:$B$1001,$A4,실물목록!$K$2:$K$1001,"있음")) -> 0 | D4: =IF($A4="","",SUMIFS(실물목록!$H$2:$H$1001,실물목록!$B$2:$B$1001,$A4,실물목록!$K$2:$K$1001,"확인필요*")) -> 0 | E4: =IF($A4="","",SUMIFS(실물목록!$H$2:$H$1001,실물목록!$B$2:$B$1001,$A4,실물목록!$K$2:$K$1001,"없음")) -> 0 | F4: =IF($A4="","",SUMIFS(실물목록!$H$2:$H$1001,실물목록!$B$2:$B$1001,$A4,실물목록!$N$2:$N$1001,"폐기후보")) -> 0 | G4: =IF($A4="","",SUMIFS(실물목록!$H$2:$H$1001,실물목록!$B$2:$B$1001,$A4,실물목록!$N$2:$N$1001,"보관")) -> 0 | H4: =IF($A4="","",SUMIFS(실물목록!$H$2:$H$1001,실물목록!$B$2:$B$1001,$A4,실물목록!$N$2:$N$1001,"등록요청")) -> 0 | I4: =IF($A4="","",SUMIFS(실물목록!$H$2:$H$1001,실물목록!$B$2:$B$1001,$A4,실물목록!$N$2:$N$1001,"확인필요")) -> 0 | J4: =IF($A4="","",SUMIFS(실물목록!$H$2:$H$1001,실물목록!$B$2:$B$1001,$A4,실물목록!$K$2:$K$1001,"<>",실물목록!$N$2:$N$1001,""))
A5: =IF(설정!A5="","",설정!A5) -> 서고 2번 선반 | B5: =IF($A5="","",SUMIFS(실물목록!$H$2:$H$1001,실물목록!$B$2:$B$1001,$A5)) | C5: =IF($A5="","",SUMIFS(실물목록!$H$2:$H$1001,실물목록!$B$2:$B$1001,$A5,실물목록!$K$2:$K$1001,"있음")) -> 0 | D5: =IF($A5="","",SUMIFS(실물목록!$H$2:$H$1001,실물목록!$B$2:$B$1001,$A5,실물목록!$K$2:$K$1001,"확인필요*")) -> 0 | E5: =IF($A5="","",SUMIFS(실물목록!$H$2:$H$1001,실물목록!$B$2:$B$1001,$A5,실물목록!$K$2:$K$1001,"없음")) -> 0 | F5: =IF($A5="","",SUMIFS(실물목록!$H$2:$H$1001,실물목록!$B$2:$B$1001,$A5,실물목록!$N$2:$N$1001,"폐기후보")) -> 0 | G5: =IF($A5="","",SUMIFS(실물목록!$H$2:$H$1001,실물목록!$B$2:$B$1001,$A5,실물목록!$N$2:$N$1001,"보관")) -> 0 | H5: =IF($A5="","",SUMIFS(실물목록!$H$2:$H$1001,실물목록!$B$2:$B$1001,$A5,실물목록!$N$2:$N$1001,"등록요청")) -> 0 | I5: =IF($A5="","",SUMIFS(실물목록!$H$2:$H$1001,실물목록!$B$2:$B$1001,$A5,실물목록!$N$2:$N$1001,"확인필요")) -> 0 | J5: =IF($A5="","",SUMIFS(실물목록!$H$2:$H$1001,실물목록!$B$2:$B$1001,$A5,실물목록!$K$2:$K$1001,"<>",실물목록!$N$2:$N$1001,""))
A6: =IF(설정!A6="","",설정!A6) | B6: =IF($A6="","",SUMIFS(실물목록!$H$2:$H$1001,실물목록!$B$2:$B$1001,$A6)) | C6: =IF($A6="","",SUMIFS(실물목록!$H$2:$H$1001,실물목록!$B$2:$B$1001,$A6,실물목록!$K$2:$K$1001,"있음")) | D6: =IF($A6="","",SUMIFS(실물목록!$H$2:$H$1001,실물목록!$B$2:$B$1001,$A6,실물목록!$K$2:$K$1001,"확인필요*")) | E6: =IF($A6="","",SUMIFS(실물목록!$H$2:$H$1001,실물목록!$B$2:$B$1001,$A6,실물목록!$K$2:$K$1001,"없음")) | F6: =IF($A6="","",SUMIFS(실물목록!$H$2:$H$1001,실물목록!$B$2:$B$1001,$A6,실물목록!$N$2:$N$1001,"폐기후보")) | G6: =IF($A6="","",SUMIFS(실물목록!$H$2:$H$1001,실물목록!$B$2:$B$1001,$A6,실물목록!$N$2:$N$1001,"보관")) | H6: =IF($A6="","",SUMIFS(실물목록!$H$2:$H$1001,실물목록!$B$2:$B$1001,$A6,실물목록!$N$2:$N$1001,"등록요청")) | I6: =IF($A6="","",SUMIFS(실물목록!$H$2:$H$1001,실물목록!$B$2:$B$1001,$A6,실물목록!$N$2:$N$1001,"확인필요")) | J6: =IF($A6="","",SUMIFS(실물목록!$H$2:$H$1001,실물목록!$B$2:$B$1001,$A6,실물목록!$K$2:$K$1001,"<>",실물목록!$N$2:$N$1001,""))
A7: =IF(설정!A7="","",설정!A7) | B7: =IF($A7="","",SUMIFS(실물목록!$H$2:$H$1001,실물목록!$B$2:$B$1001,$A7)) | C7: =IF($A7="","",SUMIFS(실물목록!$H$2:$H$1001,실물목록!$B$2:$B$1001,$A7,실물목록!$K$2:$K$1001,"있음")) | D7: =IF($A7="","",SUMIFS(실물목록!$H$2:$H$1001,실물목록!$B$2:$B$1001,$A7,실물목록!$K$2:$K$1001,"확인필요*")) | E7: =IF($A7="","",SUMIFS(실물목록!$H$2:$H$1001,실물목록!$B$2:$B$1001,$A7,실물목록!$K$2:$K$1001,"없음")) | F7: =IF($A7="","",SUMIFS(실물목록!$H$2:$H$1001,실물목록!$B$2:$B$1001,$A7,실물목록!$N$2:$N$1001,"폐기후보")) | G7: =IF($A7="","",SUMIFS(실물목록!$H$2:$H$1001,실물목록!$B$2:$B$1001,$A7,실물목록!$N$2:$N$1001,"보관")) | H7: =IF($A7="","",SUMIFS(실물목록!$H$2:$H$1001,실물목록!$B$2:$B$1001,$A7,실물목록!$N$2:$N$1001,"등록요청")) | I7: =IF($A7="","",SUMIFS(실물목록!$H$2:$H$1001,실물목록!$B$2:$B$1001,$A7,실물목록!$N$2:$N$1001,"확인필요")) | J7: =IF($A7="","",SUMIFS(실물목록!$H$2:$H$1001,실물목록!$B$2:$B$1001,$A7,실물목록!$K$2:$K$1001,"<>",실물목록!$N$2:$N$1001,""))
A8: =IF(설정!A8="","",설정!A8) | B8: =IF($A8="","",SUMIFS(실물목록!$H$2:$H$1001,실물목록!$B$2:$B$1001,$A8)) | C8: =IF($A8="","",SUMIFS(실물목록!$H$2:$H$1001,실물목록!$B$2:$B$1001,$A8,실물목록!$K$2:$K$1001,"있음")) | D8: =IF($A8="","",SUMIFS(실물목록!$H$2:$H$1001,실물목록!$B$2:$B$1001,$A8,실물목록!$K$2:$K$1001,"확인필요*")) | E8: =IF($A8="","",SUMIFS(실물목록!$H$2:$H$1001,실물목록!$B$2:$B$1001,$A8,실물목록!$K$2:$K$1001,"없음")) | F8: =IF($A8="","",SUMIFS(실물목록!$H$2:$H$1001,실물목록!$B$2:$B$1001,$A8,실물목록!$N$2:$N$1001,"폐기후보")) | G8: =IF($A8="","",SUMIFS(실물목록!$H$2:$H$1001,실물목록!$B$2:$B$1001,$A8,실물목록!$N$2:$N$1001,"보관")) | H8: =IF($A8="","",SUMIFS(실물목록!$H$2:$H$1001,실물목록!$B$2:$B$1001,$A8,실물목록!$N$2:$N$1001,"등록요청")) | I8: =IF($A8="","",SUMIFS(실물목록!$H$2:$H$1001,실물목록!$B$2:$B$1001,$A8,실물목록!$N$2:$N$1001,"확인필요")) | J8: =IF($A8="","",SUMIFS(실물목록!$H$2:$H$1001,실물목록!$B$2:$B$1001,$A8,실물목록!$K$2:$K$1001,"<>",실물목록!$N$2:$N$1001,""))
A9: =IF(설정!A9="","",설정!A9) | B9: =IF($A9="","",SUMIFS(실물목록!$H$2:$H$1001,실물목록!$B$2:$B$1001,$A9)) | C9: =IF($A9="","",SUMIFS(실물목록!$H$2:$H$1001,실물목록!$B$2:$B$1001,$A9,실물목록!$K$2:$K$1001,"있음")) | D9: =IF($A9="","",SUMIFS(실물목록!$H$2:$H$1001,실물목록!$B$2:$B$1001,$A9,실물목록!$K$2:$K$1001,"확인필요*")) | E9: =IF($A9="","",SUMIFS(실물목록!$H$2:$H$1001,실물목록!$B$2:$B$1001,$A9,실물목록!$K$2:$K$1001,"없음")) | F9: =IF($A9="","",SUMIFS(실물목록!$H$2:$H$1001,실물목록!$B$2:$B$1001,$A9,실물목록!$N$2:$N$1001,"폐기후보")) | G9: =IF($A9="","",SUMIFS(실물목록!$H$2:$H$1001,실물목록!$B$2:$B$1001,$A9,실물목록!$N$2:$N$1001,"보관")) | H9: =IF($A9="","",SUMIFS(실물목록!$H$2:$H$1001,실물목록!$B$2:$B$1001,$A9,실물목록!$N$2:$N$1001,"등록요청")) | I9: =IF($A9="","",SUMIFS(실물목록!$H$2:$H$1001,실물목록!$B$2:$B$1001,$A9,실물목록!$N$2:$N$1001,"확인필요")) | J9: =IF($A9="","",SUMIFS(실물목록!$H$2:$H$1001,실물목록!$B$2:$B$1001,$A9,실물목록!$K$2:$K$1001,"<>",실물목록!$N$2:$N$1001,""))
A10: =IF(설정!A10="","",설정!A10) | B10: =IF($A10="","",SUMIFS(실물목록!$H$2:$H$1001,실물목록!$B$2:$B$1001,$A10)) | C10: =IF($A10="","",SUMIFS(실물목록!$H$2:$H$1001,실물목록!$B$2:$B$1001,$A10,실물목록!$K$2:$K$1001,"있음")) | D10: =IF($A10="","",SUMIFS(실물목록!$H$2:$H$1001,실물목록!$B$2:$B$1001,$A10,실물목록!$K$2:$K$1001,"확인필요*")) | E10: =IF($A10="","",SUMIFS(실물목록!$H$2:$H$1001,실물목록!$B$2:$B$1001,$A10,실물목록!$K$2:$K$1001,"없음")) | F10: =IF($A10="","",SUMIFS(실물목록!$H$2:$H$1001,실물목록!$B$2:$B$1001,$A10,실물목록!$N$2:$N$1001,"폐기후보")) | G10: =IF($A10="","",SUMIFS(실물목록!$H$2:$H$1001,실물목록!$B$2:$B$1001,$A10,실물목록!$N$2:$N$1001,"보관")) | H10: =IF($A10="","",SUMIFS(실물목록!$H$2:$H$1001,실물목록!$B$2:$B$1001,$A10,실물목록!$N$2:$N$1001,"등록요청")) | I10: =IF($A10="","",SUMIFS(실물목록!$H$2:$H$1001,실물목록!$B$2:$B$1001,$A10,실물목록!$N$2:$N$1001,"확인필요")) | J10: =IF($A10="","",SUMIFS(실물목록!$H$2:$H$1001,실물목록!$B$2:$B$1001,$A10,실물목록!$K$2:$K$1001,"<>",실물목록!$N$2:$N$1001,""))
A11: =IF(설정!A11="","",설정!A11) | B11: =IF($A11="","",SUMIFS(실물목록!$H$2:$H$1001,실물목록!$B$2:$B$1001,$A11)) | C11: =IF($A11="","",SUMIFS(실물목록!$H$2:$H$1001,실물목록!$B$2:$B$1001,$A11,실물목록!$K$2:$K$1001,"있음")) | D11: =IF($A11="","",SUMIFS(실물목록!$H$2:$H$1001,실물목록!$B$2:$B$1001,$A11,실물목록!$K$2:$K$1001,"확인필요*")) | E11: =IF($A11="","",SUMIFS(실물목록!$H$2:$H$1001,실물목록!$B$2:$B$1001,$A11,실물목록!$K$2:$K$1001,"없음")) | F11: =IF($A11="","",SUMIFS(실물목록!$H$2:$H$1001,실물목록!$B$2:$B$1001,$A11,실물목록!$N$2:$N$1001,"폐기후보")) | G11: =IF($A11="","",SUMIFS(실물목록!$H$2:$H$1001,실물목록!$B$2:$B$1001,$A11,실물목록!$N$2:$N$1001,"보관")) | H11: =IF($A11="","",SUMIFS(실물목록!$H$2:$H$1001,실물목록!$B$2:$B$1001,$A11,실물목록!$N$2:$N$1001,"등록요청")) | I11: =IF($A11="","",SUMIFS(실물목록!$H$2:$H$1001,실물목록!$B$2:$B$1001,$A11,실물목록!$N$2:$N$1001,"확인필요")) | J11: =IF($A11="","",SUMIFS(실물목록!$H$2:$H$1001,실물목록!$B$2:$B$1001,$A11,실물목록!$K$2:$K$1001,"<>",실물목록!$N$2:$N$1001,""))
A12: =IF(설정!A12="","",설정!A12) | B12: =IF($A12="","",SUMIFS(실물목록!$H$2:$H$1001,실물목록!$B$2:$B$1001,$A12)) | C12: =IF($A12="","",SUMIFS(실물목록!$H$2:$H$1001,실물목록!$B$2:$B$1001,$A12,실물목록!$K$2:$K$1001,"있음")) | D12: =IF($A12="","",SUMIFS(실물목록!$H$2:$H$1001,실물목록!$B$2:$B$1001,$A12,실물목록!$K$2:$K$1001,"확인필요*")) | E12: =IF($A12="","",SUMIFS(실물목록!$H$2:$H$1001,실물목록!$B$2:$B$1001,$A12,실물목록!$K$2:$K$1001,"없음")) | F12: =IF($A12="","",SUMIFS(실물목록!$H$2:$H$1001,실물목록!$B$2:$B$1001,$A12,실물목록!$N$2:$N$1001,"폐기후보")) | G12: =IF($A12="","",SUMIFS(실물목록!$H$2:$H$1001,실물목록!$B$2:$B$1001,$A12,실물목록!$N$2:$N$1001,"보관")) | H12: =IF($A12="","",SUMIFS(실물목록!$H$2:$H$1001,실물목록!$B$2:$B$1001,$A12,실물목록!$N$2:$N$1001,"등록요청")) | I12: =IF($A12="","",SUMIFS(실물목록!$H$2:$H$1001,실물목록!$B$2:$B$1001,$A12,실물목록!$N$2:$N$1001,"확인필요")) | J12: =IF($A12="","",SUMIFS(실물목록!$H$2:$H$1001,실물목록!$B$2:$B$1001,$A12,실물목록!$K$2:$K$1001,"<>",실물목록!$N$2:$N$1001,""))
A13: =IF(설정!A13="","",설정!A13) | B13: =IF($A13="","",SUMIFS(실물목록!$H$2:$H$1001,실물목록!$B$2:$B$1001,$A13)) | C13: =IF($A13="","",SUMIFS(실물목록!$H$2:$H$1001,실물목록!$B$2:$B$1001,$A13,실물목록!$K$2:$K$1001,"있음")) | D13: =IF($A13="","",SUMIFS(실물목록!$H$2:$H$1001,실물목록!$B$2:$B$1001,$A13,실물목록!$K$2:$K$1001,"확인필요*")) | E13: =IF($A13="","",SUMIFS(실물목록!$H$2:$H$1001,실물목록!$B$2:$B$1001,$A13,실물목록!$K$2:$K$1001,"없음")) | F13: =IF($A13="","",SUMIFS(실물목록!$H$2:$H$1001,실물목록!$B$2:$B$1001,$A13,실물목록!$N$2:$N$1001,"폐기후보")) | G13: =IF($A13="","",SUMIFS(실물목록!$H$2:$H$1001,실물목록!$B$2:$B$1001,$A13,실물목록!$N$2:$N$1001,"보관")) | H13: =IF($A13="","",SUMIFS(실물목록!$H$2:$H$1001,실물목록!$B$2:$B$1001,$A13,실물목록!$N$2:$N$1001,"등록요청")) | I13: =IF($A13="","",SUMIFS(실물목록!$H$2:$H$1001,실물목록!$B$2:$B$1001,$A13,실물목록!$N$2:$N$1001,"확인필요")) | J13: =IF($A13="","",SUMIFS(실물목록!$H$2:$H$1001,실물목록!$B$2:$B$1001,$A13,실물목록!$K$2:$K$1001,"<>",실물목록!$N$2:$N$1001,""))
... A31: =IF(설정!A31="","",설정!A31) | B31: =IF($A31="","",SUMIFS(실물목록!$H$2:$H$1001,실물목록!$B$2:$B$1001,$A31)) | C31: =IF($A31="","",SUMIFS(실물목록!$H$2:$H$1001,실물목록!$B$2:$B$1001,$A31,실물목록!$K$2:$K$1001,"있음")) | D31: =IF($A31="","",SUMIFS(실물목록!$H$2:$H$1001,실물목록!$B$2:$B$1001,$A31,실물목록!$K$2:$K$1001,"확인필요*")) | E31: =IF($A31="","",SUMIFS(실물목록!$H$2:$H$1001,실물목록!$B$2:$B$1001,$A31,실물목록!$K$2:$K$1001,"없음")) | F31: =IF($A31="","",SUMIFS(실물목록!$H$2:$H$1001,실물목록!$B$2:$B$1001,$A31,실물목록!$N$2:$N$1001,"폐기후보")) | G31: =IF($A31="","",SUMIFS(실물목록!$H$2:$H$1001,실물목록!$B$2:$B$1001,$A31,실물목록!$N$2:$N$1001,"보관")) | H31: =IF($A31="","",SUMIFS(실물목록!$H$2:$H$1001,실물목록!$B$2:$B$1001,$A31,실물목록!$N$2:$N$1001,"등록요청")) | I31: =IF($A31="","",SUMIFS(실물목록!$H$2:$H$1001,실물목록!$B$2:$B$1001,$A31,실물목록!$N$2:$N$1001,"확인필요")) | J31: =IF($A31="","",SUMIFS(실물목록!$H$2:$H$1001,실물목록!$B$2:$B$1001,$A31,실물목록!$K$2:$K$1001,"<>",실물목록!$N$2:$N$1001,""))
A33: 합계 | B33: =SUM(B2:B31) -> 1 | C33: =SUM(C2:C31) -> 1 | D33: =SUM(D2:D31) -> 0 | E33: =SUM(E2:E31) -> 0 | F33: =SUM(F2:F31) -> 1 | G33: =SUM(G2:G31) -> 0 | H33: =SUM(H2:H31) -> 0 | I33: =SUM(I2:I31) -> 0 | J33: =SUM(J2:J31) -> 0
A34: =IF(SUMIFS(실물목록!$H$2:$H$1001,실물목록!$K$2:$K$1001,"<>",실물목록!$B$2:$B$1001,"")>0,"※ 보관위치를 안 고른 행 "&SUMIFS(실물목록!$H$2:$H$1001,실물목록!$K$2:$K$1001,"<>",실물목록!$B$2:$B$1001,"")&"권은 위 표에서 빠져 있습니다","")
